Workbook

Sheet COVER
B3: BridgeToRetired
B4: PRO RETIREMENT BRIDGE PLANNER
B5: Version 3.1 · 2026 Tax Year · bridgetoretired.com
B10: WHAT'S INSIDE
B11: INPUTS | C11: Ages, balances, spending, state, filing status — single entry point for all sheets
B12: BRIDGE | C12: Year-by-year funding plan retirement → 59½ with Taxable → Roth → 401k cascade
B13: TAX ESTIMATE | C13: Federal tax per bridge year — MFJ or Single brackets switchable in INPUTS
B14: ROTH LADDER | C14: Optimal Roth conversions with 12% bracket space and ACA cliff cross-check per year
B15: POST-59.5 | C15: Portfolio projection 59½ → life expectancy with Social Security income modeled
B16: MONTE CARLO | C16: 200-scenario simulator — plan success rate across randomized return sequences
B17: RISK FLAGS | C17: 9 automated checks: withdrawal rate, ACA cliff, IRMAA, SS delay, Monte Carlo
B18: REBALANCE | C18: Annual target vs actual allocation by asset class with drift alerts and signals
B20: COLOR CODING GUIDE
B22: Blue text = Input cells — change these to your numbers
B23: Green text = Linked from another sheet
B24: Black text = Formula / calculated — do not edit
B25: Gold highlight = Key result or flag
B27: ⚠ Not financial advice. For modeling purposes only. Consult a qualified fee-only advisor.
B29: v3.1 (Aug 2026): 2026 brackets & std deduction · ACA cliff by household size · balances grown to retirement date · retire-at-60+ fix · capacity: 25-yr bridge, 45-yr projection, 60-yr Monte Carlo

Sheet INPUTS
A1: RETIREMENT INPUTS
A2: Blue cells are inputs. Change any value — every sheet updates automatically.
A3: PERSONAL
A4: PERSONAL
A5: Current Age | B5: 52
A6: Planned Retirement Age | B6: 55
A7: Social Security Claiming Age | B7: 67 | D7: 62 / 67 / 70
A8: Life Expectancy (planning age) | B8: 90 | D8: Conservative = 90–95
A9: Filing Status | B9: MFJ | D9: MFJ or Single — drives TAX ESTIMATE brackets
A10: State of Residence | B10: TX | D10: No-tax states: AK FL NV NH SD TN TX WA WY
A11: State Tax Rate (if any) | B11: 0 | D11: 0% for the 9 no-tax states; else your flat est.
A12: First Projection Year | B12: 2026
A13: PORTFOLIO BALANCES
A14: PORTFOLIO BALANCES (TODAY)
A15: Taxable Brokerage | B15: 350000
A16: Traditional 401k / IRA | B16: 650000
A17: Roth IRA / Roth 401k | B17: 150000
A18: Cash / Money Market | B18: 75000 | D18: Bridge buffer — counted in taxable cascade
A19: Total Portfolio (today) | B19: =B15+B16+B17+B18 -> 1225000
A21: SPENDING & INCOME
A22: Annual Spending (today $) | B22: 55000
A23: Inflation Rate | B23: 0.025
A24: Other Income ($/yr, today $) | B24: 0 | D24: Pension, rental, part-time — applied every year
A25: Estimated Social Security ($/yr today $) | B25: 24000 | D25: At claiming age
A26: ACA Household Size | B26: 2 | D26: People on your marketplace plan — sets the 400% FPL cliff
A27: RETURN ASSUMPTIONS
A28: Expected Return (nominal) | B28: 0.065 | D28: Long-run nominal. 60/40 ≈ 6–7%. Also the Monte Carlo mean.
A29: Portfolio Volatility (std dev) | B29: 0.12 | D29: Used by MONTE CARLO. 60/40 ≈ 10–12%
A31: AUTO-CALCULATED
A32: Bridge Length (years) | B32: =MAX(0, 59.5 - B6) -> 4.5
A33: Withdrawal Rate (at retirement) | B33: =B22*(1+B23)^MAX(0,B6-B5)/B35 -> 0.040026662
A34: Std Deduction (2026) | B34: =IF(B9="MFJ",32200,16100) -> 32200
A35: Portfolio at Retirement (est.) | B35: =B19*(1+B28)^MAX(0,B6-B5) -> 1479738.3 | D35: Today's balances grown at Expected Return to retirement — excludes new contributions

Sheet BRIDGE
A1: BRIDGE FUNDING PLAN · Retirement to Age 59½
A2: =IF(INPUTS!$B$32=0,"No bridge needed — retiring at or after age 59½. See POST-59.5 for your projection.","Withdrawal cascade: Taxable+Cash first → Roth → 401k. Starting balances = today's balances grown to retirement age.") -> Withdrawal cascade: Taxable+Cash first → Roth → 401k. Starting balances = today's balances grown to retirement age.
A3: Year | B3: Age | C3: Spending (Inflated) | D3: Other Income | E3: Net Needed | F3: Taxable+Cash Start | G3: Roth Start | H3: 401k Start | I3: From Taxable | J3: From Roth | K3: From 401k | L3: Taxable End | M3: Roth End | N3: 401k End | O3: Total End
A4: =IF(INPUTS!$B$32=0,"",IF(0>=INPUTS!$B$32,"",INPUTS!$B$12+(INPUTS!$B$6-INPUTS!$B$5)+0)) -> 2029 | B4: =IF(INPUTS!$B$32=0,"",IF(0>=INPUTS!$B$32,"",INPUTS!$B$6+0)) -> 55 | C4: =IF(INPUTS!$B$32=0,"",IF(0>=INPUTS!$B$32,"",INPUTS!$B$22*(1+INPUTS!$B$23)^(INPUTS!$B$6-INPUTS!$B$5+0))) -> 59228.984 | D4: =IF(INPUTS!$B$32=0,"",IF(0>=INPUTS!$B$32,"",INPUTS!$B$24)) -> 0 | E4: =IF(INPUTS!$B$32=0,"",IF(0>=INPUTS!$B$32,"",MAX(0,C4-D4))) -> 59228.984 | F4: =IF(INPUTS!$B$32=0,"",IF(0>=INPUTS!$B$32,"",(INPUTS!$B$15+INPUTS!$B$18)*(1+INPUTS!$B$28)^MAX(0,INPUTS!$B$6-INPUTS!$B$5))) -> 513378.59 | G4: =IF(INPUTS!$B$32=0,"",IF(0>=INPUTS!$B$32,"",INPUTS!$B$17*(1+INPUTS!$B$28)^MAX(0,INPUTS!$B$6-INPUTS!$B$5))) -> 181192.44 | H4: =IF(INPUTS!$B$32=0,"",IF(0>=INPUTS!$B$32,"",INPUTS!$B$16*(1+INPUTS!$B$28)^MAX(0,INPUTS!$B$6-INPUTS!$B$5))) -> 785167.26 | I4: =IF(INPUTS!$B$32=0,"",IF(0>=INPUTS!$B$32,"",MIN(E4,F4))) -> 59228.984 | J4: =IF(INPUTS!$B$32=0,"",IF(0>=INPUTS!$B$32,"",MIN(E4-I4,G4))) -> 0 | K4: =IF(INPUTS!$B$32=0,"",IF(0>=INPUTS!$B$32,"",MIN(E4-I4-J4,H4))) -> 0 | L4: =IF(INPUTS!$B$32=0,"",IF(0>=INPUTS!$B$32,"",(F4-I4)*(1+INPUTS!$B$28))) -> 483669.33 | M4: =IF(INPUTS!$B$32=0,"",IF(0>=INPUTS!$B$32,"",(G4-J4)*(1+INPUTS!$B$28))) -> 192969.95 | N4: =IF(INPUTS!$B$32=0,"",IF(0>=INPUTS!$B$32,"",(H4-K4)*(1+INPUTS!$B$28))) -> 836203.13 | O4: =IF(INPUTS!$B$32=0,"",IF(0>=INPUTS!$B$32,"",L4+M4+N4)) -> 1512842.4
A5: =IF(INPUTS!$B$32=0,"",IF(1>=INPUTS!$B$32,"",INPUTS!$B$12+(INPUTS!$B$6-INPUTS!$B$5)+1)) -> 2030 | B5: =IF(INPUTS!$B$32=0,"",IF(1>=INPUTS!$B$32,"",INPUTS!$B$6+1)) -> 56 | C5: =IF(INPUTS!$B$32=0,"",IF(1>=INPUTS!$B$32,"",INPUTS!$B$22*(1+INPUTS!$B$23)^(INPUTS!$B$6-INPUTS!$B$5+1))) -> 60709.709 | D5: =IF(INPUTS!$B$32=0,"",IF(1>=INPUTS!$B$32,"",INPUTS!$B$24)) -> 0 | E5: =IF(INPUTS!$B$32=0,"",IF(1>=INPUTS!$B$32,"",MAX(0,C5-D5))) -> 60709.709 | F5: =IF(INPUTS!$B$32=0,"",IF(1>=INPUTS!$B$32,"",L4)) -> 483669.33 | G5: =IF(INPUTS!$B$32=0,"",IF(1>=INPUTS!$B$32,"",M4)) -> 192969.95 | H5: =IF(INPUTS!$B$32=0,"",IF(1>=INPUTS!$B$32,"",N4)) -> 836203.13 | I5: =IF(INPUTS!$B$32=0,"",IF(1>=INPUTS!$B$32,"",MIN(E5,F5))) -> 60709.709 | J5: =IF(INPUTS!$B$32=0,"",IF(1>=INPUTS!$B$32,"",MIN(E5-I5,G5))) -> 0 | K5: =IF(INPUTS!$B$32=0,"",IF(1>=INPUTS!$B$32,"",MIN(E5-I5-J5,H5))) -> 0 | L5: =IF(INPUTS!$B$32=0,"",IF(1>=INPUTS!$B$32,"",(F5-I5)*(1+INPUTS!$B$28))) -> 450452 | M5: =IF(INPUTS!$B$32=0,"",IF(1>=INPUTS!$B$32,"",(G5-J5)*(1+INPUTS!$B$28))) -> 205513 | N5: =IF(INPUTS!$B$32=0,"",IF(1>=INPUTS!$B$32,"",(H5-K5)*(1+INPUTS!$B$28))) -> 890556.33 | O5: =IF(INPUTS!$B$32=0,"",IF(1>=INPUTS!$B$32,"",L5+M5+N5)) -> 1546521.3
A6: =IF(INPUTS!$B$32=0,"",IF(2>=INPUTS!$B$32,"",INPUTS!$B$12+(INPUTS!$B$6-INPUTS!$B$5)+2)) -> 2031 | B6: =IF(INPUTS!$B$32=0,"",IF(2>=INPUTS!$B$32,"",INPUTS!$B$6+2)) -> 57 | C6: =IF(INPUTS!$B$32=0,"",IF(2>=INPUTS!$B$32,"",INPUTS!$B$22*(1+INPUTS!$B$23)^(INPUTS!$B$6-INPUTS!$B$5+2))) -> 62227.452 | D6: =IF(INPUTS!$B$32=0,"",IF(2>=INPUTS!$B$32,"",INPUTS!$B$24)) -> 0 | E6: =IF(INPUTS!$B$32=0,"",IF(2>=INPUTS!$B$32,"",MAX(0,C6-D6))) -> 62227.452 | F6: =IF(INPUTS!$B$32=0,"",IF(2>=INPUTS!$B$32,"",L5)) -> 450452 | G6: =IF(INPUTS!$B$32=0,"",IF(2>=INPUTS!$B$32,"",M5)) -> 205513 | H6: =IF(INPUTS!$B$32=0,"",IF(2>=INPUTS!$B$32,"",N5)) -> 890556.33 | I6: =IF(INPUTS!$B$32=0,"",IF(2>=INPUTS!$B$32,"",MIN(E6,F6))) -> 62227.452 | J6: =IF(INPUTS!$B$32=0,"",IF(2>=INPUTS!$B$32,"",MIN(E6-I6,G6))) -> 0 | K6: =IF(INPUTS!$B$32=0,"",IF(2>=INPUTS!$B$32,"",MIN(E6-I6-J6,H6))) -> 0 | L6: =IF(INPUTS!$B$32=0,"",IF(2>=INPUTS!$B$32,"",(F6-I6)*(1+INPUTS!$B$28))) -> 413459.14 | M6: =IF(INPUTS!$B$32=0,"",IF(2>=INPUTS!$B$32,"",(G6-J6)*(1+INPUTS!$B$28))) -> 218871.34 | N6: =IF(INPUTS!$B$32=0,"",IF(2>=INPUTS!$B$32,"",(H6-K6)*(1+INPUTS!$B$28))) -> 948442.49 | O6: =IF(INPUTS!$B$32=0,"",IF(2>=INPUTS!$B$32,"",L6+M6+N6)) -> 1580773
A7: =IF(INPUTS!$B$32=0,"",IF(3>=INPUTS!$B$32,"",INPUTS!$B$12+(INPUTS!$B$6-INPUTS!$B$5)+3)) -> 2032 | B7: =IF(INPUTS!$B$32=0,"",IF(3>=INPUTS!$B$32,"",INPUTS!$B$6+3)) -> 58 | C7: =IF(INPUTS!$B$32=0,"",IF(3>=INPUTS!$B$32,"",INPUTS!$B$22*(1+INPUTS!$B$23)^(INPUTS!$B$6-INPUTS!$B$5+3))) -> 63783.138 | D7: =IF(INPUTS!$B$32=0,"",IF(3>=INPUTS!$B$32,"",INPUTS!$B$24)) -> 0 | E7: =IF(INPUTS!$B$32=0,"",IF(3>=INPUTS!$B$32,"",MAX(0,C7-D7))) -> 63783.138 | F7: =IF(INPUTS!$B$32=0,"",IF(3>=INPUTS!$B$32,"",L6)) -> 413459.14 | G7: =IF(INPUTS!$B$32=0,"",IF(3>=INPUTS!$B$32,"",M6)) -> 218871.34 | H7: =IF(INPUTS!$B$32=0,"",IF(3>=INPUTS!$B$32,"",N6)) -> 948442.49 | I7: =IF(INPUTS!$B$32=0,"",IF(3>=INPUTS!$B$32,"",MIN(E7,F7))) -> 63783.138 | J7: =IF(INPUTS!$B$32=0,"",IF(3>=INPUTS!$B$32,"",MIN(E7-I7,G7))) -> 0 | K7: =IF(INPUTS!$B$32=0,"",IF(3>=INPUTS!$B$32,"",MIN(E7-I7-J7,H7))) -> 0 | L7: =IF(INPUTS!$B$32=0,"",IF(3>=INPUTS!$B$32,"",(F7-I7)*(1+INPUTS!$B$28))) -> 372404.94 | M7: =IF(INPUTS!$B$32=0,"",IF(3>=INPUTS!$B$32,"",(G7-J7)*(1+INPUTS!$B$28))) -> 233097.98 | N7: =IF(INPUTS!$B$32=0,"",IF(3>=INPUTS!$B$32,"",(H7-K7)*(1+INPUTS!$B$28))) -> 1010091.3 | O7: =IF(INPUTS!$B$32=0,"",IF(3>=INPUTS!$B$32,"",L7+M7+N7)) -> 1615594.2
A8: =IF(INPUTS!$B$32=0,"",IF(4>=INPUTS!$B$32,"",INPUTS!$B$12+(INPUTS!$B$6-INPUTS!$B$5)+4)) -> 2033 | B8: =IF(INPUTS!$B$32=0,"",IF(4>=INPUTS!$B$32,"",INPUTS!$B$6+4)) -> 59 | C8: =IF(INPUTS!$B$32=0,"",IF(4>=INPUTS!$B$32,"",INPUTS!$B$22*(1+INPUTS!$B$23)^(INPUTS!$B$6-INPUTS!$B$5+4))) -> 65377.716 | D8: =IF(INPUTS!$B$32=0,"",IF(4>=INPUTS!$B$32,"",INPUTS!$B$24)) -> 0 | E8: =IF(INPUTS!$B$32=0,"",IF(4>=INPUTS!$B$32,"",MAX(0,C8-D8))) -> 65377.716 | F8: =IF(INPUTS!$B$32=0,"",IF(4>=INPUTS!$B$32,"",L7)) -> 372404.94 | G8: =IF(INPUTS!$B$32=0,"",IF(4>=INPUTS!$B$32,"",M7)) -> 233097.98 | H8: =IF(INPUTS!$B$32=0,"",IF(4>=INPUTS!$B$32,"",N7)) -> 1010091.3 | I8: =IF(INPUTS!$B$32=0,"",IF(4>=INPUTS!$B$32,"",MIN(E8,F8))) -> 65377.716 | J8: =IF(INPUTS!$B$32=0,"",IF(4>=INPUTS!$B$32,"",MIN(E8-I8,G8))) -> 0 | K8: =IF(INPUTS!$B$32=0,"",IF(4>=INPUTS!$B$32,"",MIN(E8-I8-J8,H8))) -> 0 | L8: =IF(INPUTS!$B$32=0,"",IF(4>=INPUTS!$B$32,"",(F8-I8)*(1+INPUTS!$B$28))) -> 326984 | M8: =IF(INPUTS!$B$32=0,"",IF(4>=INPUTS!$B$32,"",(G8-J8)*(1+INPUTS!$B$28))) -> 248249.35 | N8: =IF(INPUTS!$B$32=0,"",IF(4>=INPUTS!$B$32,"",(H8-K8)*(1+INPUTS!$B$28))) -> 1075747.2 | O8: =IF(INPUTS!$B$32=0,"",IF(4>=INPUTS!$B$32,"",L8+M8+N8)) -> 1650980.5
A9: =IF(INPUTS!$B$32=0,"",IF(5>=INPUTS!$B$32,"",INPUTS!$B$12+(INPUTS!$B$6-INPUTS!$B$5)+5)) | B9: =IF(INPUTS!$B$32=0,"",IF(5>=INPUTS!$B$32,"",INPUTS!$B$6+5)) | C9: =IF(INPUTS!$B$32=0,"",IF(5>=INPUTS!$B$32,"",INPUTS!$B$22*(1+INPUTS!$B$23)^(INPUTS!$B$6-INPUTS!$B$5+5))) | D9: =IF(INPUTS!$B$32=0,"",IF(5>=INPUTS!$B$32,"",INPUTS!$B$24)) | E9: =IF(INPUTS!$B$32=0,"",IF(5>=INPUTS!$B$32,"",MAX(0,C9-D9))) | F9: =IF(INPUTS!$B$32=0,"",IF(5>=INPUTS!$B$32,"",L8)) | G9: =IF(INPUTS!$B$32=0,"",IF(5>=INPUTS!$B$32,"",M8)) | H9: =IF(INPUTS!$B$32=0,"",IF(5>=INPUTS!$B$32,"",N8)) | I9: =IF(INPUTS!$B$32=0,"",IF(5>=INPUTS!$B$32,"",MIN(E9,F9))) | J9: =IF(INPUTS!$B$32=0,"",IF(5>=INPUTS!$B$32,"",MIN(E9-I9,G9))) | K9: =IF(INPUTS!$B$32=0,"",IF(5>=INPUTS!$B$32,"",MIN(E9-I9-J9,H9))) | L9: =IF(INPUTS!$B$32=0,"",IF(5>=INPUTS!$B$32,"",(F9-I9)*(1+INPUTS!$B$28))) | M9: =IF(INPUTS!$B$32=0,"",IF(5>=INPUTS!$B$32,"",(G9-J9)*(1+INPUTS!$B$28))) | N9: =IF(INPUTS!$B$32=0,"",IF(5>=INPUTS!$B$32,"",(H9-K9)*(1+INPUTS!$B$28))) | O9: =IF(INPUTS!$B$32=0,"",IF(5>=INPUTS!$B$32,"",L9+M9+N9))
A10: =IF(INPUTS!$B$32=0,"",IF(6>=INPUTS!$B$32,"",INPUTS!$B$12+(INPUTS!$B$6-INPUTS!$B$5)+6)) | B10: =IF(INPUTS!$B$32=0,"",IF(6>=INPUTS!$B$32,"",INPUTS!$B$6+6)) | C10: =IF(INPUTS!$B$32=0,"",IF(6>=INPUTS!$B$32,"",INPUTS!$B$22*(1+INPUTS!$B$23)^(INPUTS!$B$6-INPUTS!$B$5+6))) | D10: =IF(INPUTS!$B$32=0,"",IF(6>=INPUTS!$B$32,"",INPUTS!$B$24)) | E10: =IF(INPUTS!$B$32=0,"",IF(6>=INPUTS!$B$32,"",MAX(0,C10-D10))) | F10: =IF(INPUTS!$B$32=0,"",IF(6>=INPUTS!$B$32,"",L9)) | G10: =IF(INPUTS!$B$32=0,"",IF(6>=INPUTS!$B$32,"",M9)) | H10: =IF(INPUTS!$B$32=0,"",IF(6>=INPUTS!$B$32,"",N9)) | I10: =IF(INPUTS!$B$32=0,"",IF(6>=INPUTS!$B$32,"",MIN(E10,F10))) | J10: =IF(INPUTS!$B$32=0,"",IF(6>=INPUTS!$B$32,"",MIN(E10-I10,G10))) | K10: =IF(INPUTS!$B$32=0,"",IF(6>=INPUTS!$B$32,"",MIN(E10-I10-J10,H10))) | L10: =IF(INPUTS!$B$32=0,"",IF(6>=INPUTS!$B$32,"",(F10-I10)*(1+INPUTS!$B$28))) | M10: =IF(INPUTS!$B$32=0,"",IF(6>=INPUTS!$B$32,"",(G10-J10)*(1+INPUTS!$B$28))) | N10: =IF(INPUTS!$B$32=0,"",IF(6>=INPUTS!$B$32,"",(H10-K10)*(1+INPUTS!$B$28))) | O10: =IF(INPUTS!$B$32=0,"",IF(6>=INPUTS!$B$32,"",L10+M10+N10))
A11: =IF(INPUTS!$B$32=0,"",IF(7>=INPUTS!$B$32,"",INPUTS!$B$12+(INPUTS!$B$6-INPUTS!$B$5)+7)) | B11: =IF(INPUTS!$B$32=0,"",IF(7>=INPUTS!$B$32,"",INPUTS!$B$6+7)) | C11: =IF(INPUTS!$B$32=0,"",IF(7>=INPUTS!$B$32,"",INPUTS!$B$22*(1+INPUTS!$B$23)^(INPUTS!$B$6-INPUTS!$B$5+7))) | D11: =IF(INPUTS!$B$32=0,"",IF(7>=INPUTS!$B$32,"",INPUTS!$B$24)) | E11: =IF(INPUTS!$B$32=0,"",IF(7>=INPUTS!$B$32,"",MAX(0,C11-D11))) | F11: =IF(INPUTS!$B$32=0,"",IF(7>=INPUTS!$B$32,"",L10)) | G11: =IF(INPUTS!$B$32=0,"",IF(7>=INPUTS!$B$32,"",M10)) | H11: =IF(INPUTS!$B$32=0,"",IF(7>=INPUTS!$B$32,"",N10)) | I11: =IF(INPUTS!$B$32=0,"",IF(7>=INPUTS!$B$32,"",MIN(E11,F11))) | J11: =IF(INPUTS!$B$32=0,"",IF(7>=INPUTS!$B$32,"",MIN(E11-I11,G11))) | K11: =IF(INPUTS!$B$32=0,"",IF(7>=INPUTS!$B$32,"",MIN(E11-I11-J11,H11))) | L11: =IF(INPUTS!$B$32=0,"",IF(7>=INPUTS!$B$32,"",(F11-I11)*(1+INPUTS!$B$28))) | M11: =IF(INPUTS!$B$32=0,"",IF(7>=INPUTS!$B$32,"",(G11-J11)*(1+INPUTS!$B$28))) | N11: =IF(INPUTS!$B$32=0,"",IF(7>=INPUTS!$B$32,"",(H11-K11)*(1+INPUTS!$B$28))) | O11: =IF(INPUTS!$B$32=0,"",IF(7>=INPUTS!$B$32,"",L11+M11+N11))
A12: =IF(INPUTS!$B$32=0,"",IF(8>=INPUTS!$B$32,"",INPUTS!$B$12+(INPUTS!$B$6-INPUTS!$B$5)+8)) | B12: =IF(INPUTS!$B$32=0,"",IF(8>=INPUTS!$B$32,"",INPUTS!$B$6+8)) | C12: =IF(INPUTS!$B$32=0,"",IF(8>=INPUTS!$B$32,"",INPUTS!$B$22*(1+INPUTS!$B$23)^(INPUTS!$B$6-INPUTS!$B$5+8))) | D12: =IF(INPUTS!$B$32=0,"",IF(8>=INPUTS!$B$32,"",INPUTS!$B$24)) | E12: =IF(INPUTS!$B$32=0,"",IF(8>=INPUTS!$B$32,"",MAX(0,C12-D12))) | F12: =IF(INPUTS!$B$32=0,"",IF(8>=INPUTS!$B$32,"",L11)) | G12: =IF(INPUTS!$B$32=0,"",IF(8>=INPUTS!$B$32,"",M11)) | H12: =IF(INPUTS!$B$32=0,"",IF(8>=INPUTS!$B$32,"",N11)) | I12: =IF(INPUTS!$B$32=0,"",IF(8>=INPUTS!$B$32,"",MIN(E12,F12))) | J12: =IF(INPUTS!$B$32=0,"",IF(8>=INPUTS!$B$32,"",MIN(E12-I12,G12))) | K12: =IF(INPUTS!$B$32=0,"",IF(8>=INPUTS!$B$32,"",MIN(E12-I12-J12,H12))) | L12: =IF(INPUTS!$B$32=0,"",IF(8>=INPUTS!$B$32,"",(F12-I12)*(1+INPUTS!$B$28))) | M12: =IF(INPUTS!$B$32=0,"",IF(8>=INPUTS!$B$32,"",(G12-J12)*(1+INPUTS!$B$28))) | N12: =IF(INPUTS!$B$32=0,"",IF(8>=INPUTS!$B$32,"",(H12-K12)*(1+INPUTS!$B$28))) | O12: =IF(INPUTS!$B$32=0,"",IF(8>=INPUTS!$B$32,"",L12+M12+N12))
A13: =IF(INPUTS!$B$32=0,"",IF(9>=INPUTS!$B$32,"",INPUTS!$B$12+(INPUTS!$B$6-INPUTS!$B$5)+9)) | B13: =IF(INPUTS!$B$32=0,"",IF(9>=INPUTS!$B$32,"",INPUTS!$B$6+9)) | C13: =IF(INPUTS!$B$32=0,"",IF(9>=INPUTS!$B$32,"",INPUTS!$B$22*(1+INPUTS!$B$23)^(INPUTS!$B$6-INPUTS!$B$5+9))) | D13: =IF(INPUTS!$B$32=0,"",IF(9>=INPUTS!$B$32,"",INPUTS!$B$24)) | E13: =IF(INPUTS!$B$32=0,"",IF(9>=INPUTS!$B$32,"",MAX(0,C13-D13))) | F13: =IF(INPUTS!$B$32=0,"",IF(9>=INPUTS!$B$32,"",L12)) | G13: =IF(INPUTS!$B$32=0,"",IF(9>=INPUTS!$B$32,"",M12)) | H13: =IF(INPUTS!$B$32=0,"",IF(9>=INPUTS!$B$32,"",N12)) | I13: =IF(INPUTS!$B$32=0,"",IF(9>=INPUTS!$B$32,"",MIN(E13,F13))) | J13: =IF(INPUTS!$B$32=0,"",IF(9>=INPUTS!$B$32,"",MIN(E13-I13,G13))) | K13: =IF(INPUTS!$B$32=0,"",IF(9>=INPUTS!$B$32,"",MIN(E13-I13-J13,H13))) | L13: =IF(INPUTS!$B$32=0,"",IF(9>=INPUTS!$B$32,"",(F13-I13)*(1+INPUTS!$B$28))) | M13: =IF(INPUTS!$B$32=0,"",IF(9>=INPUTS!$B$32,"",(G13-J13)*(1+INPUTS!$B$28))) | N13: =IF(INPUTS!$B$32=0,"",IF(9>=INPUTS!$B$32,"",(H13-K13)*(1+INPUTS!$B$28))) | O13: =IF(INPUTS!$B$32=0,"",IF(9>=INPUTS!$B$32,"",L13+M13+N13))
A14: =IF(INPUTS!$B$32=0,"",IF(10>=INPUTS!$B$32,"",INPUTS!$B$12+(INPUTS!$B$6-INPUTS!$B$5)+10)) | B14: =IF(INPUTS!$B$32=0,"",IF(10>=INPUTS!$B$32,"",INPUTS!$B$6+10)) | C14: =IF(INPUTS!$B$32=0,"",IF(10>=INPUTS!$B$32,"",INPUTS!$B$22*(1+INPUTS!$B$23)^(INPUTS!$B$6-INPUTS!$B$5+10))) | D14: =IF(INPUTS!$B$32=0,"",IF(10>=INPUTS!$B$32,"",INPUTS!$B$24)) | E14: =IF(INPUTS!$B$32=0,"",IF(10>=INPUTS!$B$32,"",MAX(0,C14-D14))) | F14: =IF(INPUTS!$B$32=0,"",IF(10>=INPUTS!$B$32,"",L13)) | G14: =IF(INPUTS!$B$32=0,"",IF(10>=INPUTS!$B$32,"",M13)) | H14: =IF(INPUTS!$B$32=0,"",IF(10>=INPUTS!$B$32,"",N13)) | I14: =IF(INPUTS!$B$32=0,"",IF(10>=INPUTS!$B$32,"",MIN(E14,F14))) | J14: =IF(INPUTS!$B$32=0,"",IF(10>=INPUTS!$B$32,"",MIN(E14-I14,G14))) | K14: =IF(INPUTS!$B$32=0,"",IF(10>=INPUTS!$B$32,"",MIN(E14-I14-J14,H14))) | L14: =IF(INPUTS!$B$32=0,"",IF(10>=INPUTS!$B$32,"",(F14-I14)*(1+INPUTS!$B$28))) | M14: =IF(INPUTS!$B$32=0,"",IF(10>=INPUTS!$B$32,"",(G14-J14)*(1+INPUTS!$B$28))) | N14: =IF(INPUTS!$B$32=0,"",IF(10>=INPUTS!$B$32,"",(H14-K14)*(1+INPUTS!$B$28))) | O14: =IF(INPUTS!$B$32=0,"",IF(10>=INPUTS!$B$32,"",L14+M14+N14))
A15: =IF(INPUTS!$B$32=0,"",IF(11>=INPUTS!$B$32,"",INPUTS!$B$12+(INPUTS!$B$6-INPUTS!$B$5)+11)) | B15: =IF(INPUTS!$B$32=0,"",IF(11>=INPUTS!$B$32,"",INPUTS!$B$6+11)) | C15: =IF(INPUTS!$B$32=0,"",IF(11>=INPUTS!$B$32,"",INPUTS!$B$22*(1+INPUTS!$B$23)^(INPUTS!$B$6-INPUTS!$B$5+11))) | D15: =IF(INPUTS!$B$32=0,"",IF(11>=INPUTS!$B$32,"",INPUTS!$B$24)) | E15: =IF(INPUTS!$B$32=0,"",IF(11>=INPUTS!$B$32,"",MAX(0,C15-D15))) | F15: =IF(INPUTS!$B$32=0,"",IF(11>=INPUTS!$B$32,"",L14)) | G15: =IF(INPUTS!$B$32=0,"",IF(11>=INPUTS!$B$32,"",M14)) | H15: =IF(INPUTS!$B$32=0,"",IF(11>=INPUTS!$B$32,"",N14)) | I15: =IF(INPUTS!$B$32=0,"",IF(11>=INPUTS!$B$32,"",MIN(E15,F15))) | J15: =IF(INPUTS!$B$32=0,"",IF(11>=INPUTS!$B$32,"",MIN(E15-I15,G15))) | K15: =IF(INPUTS!$B$32=0,"",IF(11>=INPUTS!$B$32,"",MIN(E15-I15-J15,H15))) | L15: =IF(INPUTS!$B$32=0,"",IF(11>=INPUTS!$B$32,"",(F15-I15)*(1+INPUTS!$B$28))) | M15: =IF(INPUTS!$B$32=0,"",IF(11>=INPUTS!$B$32,"",(G15-J15)*(1+INPUTS!$B$28))) | N15: =IF(INPUTS!$B$32=0,"",IF(11>=INPUTS!$B$32,"",(H15-K15)*(1+INPUTS!$B$28))) | O15: =IF(INPUTS!$B$32=0,"",IF(11>=INPUTS!$B$32,"",L15+M15+N15))
A16: =IF(INPUTS!$B$32=0,"",IF(12>=INPUTS!$B$32,"",INPUTS!$B$12+(INPUTS!$B$6-INPUTS!$B$5)+12)) | B16: =IF(INPUTS!$B$32=0,"",IF(12>=INPUTS!$B$32,"",INPUTS!$B$6+12)) | C16: =IF(INPUTS!$B$32=0,"",IF(12>=INPUTS!$B$32,"",INPUTS!$B$22*(1+INPUTS!$B$23)^(INPUTS!$B$6-INPUTS!$B$5+12))) | D16: =IF(INPUTS!$B$32=0,"",IF(12>=INPUTS!$B$32,"",INPUTS!$B$24)) | E16: =IF(INPUTS!$B$32=0,"",IF(12>=INPUTS!$B$32,"",MAX(0,C16-D16))) | F16: =IF(INPUTS!$B$32=0,"",IF(12>=INPUTS!$B$32,"",L15)) | G16: =IF(INPUTS!$B$32=0,"",IF(12>=INPUTS!$B$32,"",M15)) | H16: =IF(INPUTS!$B$32=0,"",IF(12>=INPUTS!$B$32,"",N15)) | I16: =IF(INPUTS!$B$32=0,"",IF(12>=INPUTS!$B$32,"",MIN(E16,F16))) | J16: =IF(INPUTS!$B$32=0,"",IF(12>=INPUTS!$B$32,"",MIN(E16-I16,G16))) | K16: =IF(INPUTS!$B$32=0,"",IF(12>=INPUTS!$B$32,"",MIN(E16-I16-J16,H16))) | L16: =IF(INPUTS!$B$32=0,"",IF(12>=INPUTS!$B$32,"",(F16-I16)*(1+INPUTS!$B$28))) | M16: =IF(INPUTS!$B$32=0,"",IF(12>=INPUTS!$B$32,"",(G16-J16)*(1+INPUTS!$B$28))) | N16: =IF(INPUTS!$B$32=0,"",IF(12>=INPUTS!$B$32,"",(H16-K16)*(1+INPUTS!$B$28))) | O16: =IF(INPUTS!$B$32=0,"",IF(12>=INPUTS!$B$32,"",L16+M16+N16))
A17: =IF(INPUTS!$B$32=0,"",IF(13>=INPUTS!$B$32,"",INPUTS!$B$12+(INPUTS!$B$6-INPUTS!$B$5)+13)) | B17: =IF(INPUTS!$B$32=0,"",IF(13>=INPUTS!$B$32,"",INPUTS!$B$6+13)) | C17: =IF(INPUTS!$B$32=0,"",IF(13>=INPUTS!$B$32,"",INPUTS!$B$22*(1+INPUTS!$B$23)^(INPUTS!$B$6-INPUTS!$B$5+13))) | D17: =IF(INPUTS!$B$32=0,"",IF(13>=INPUTS!$B$32,"",INPUTS!$B$24)) | E17: =IF(INPUTS!$B$32=0,"",IF(13>=INPUTS!$B$32,"",MAX(0,C17-D17))) | F17: =IF(INPUTS!$B$32=0,"",IF(13>=INPUTS!$B$32,"",L16)) | G17: =IF(INPUTS!$B$32=0,"",IF(13>=INPUTS!$B$32,"",M16)) | H17: =IF(INPUTS!$B$32=0,"",IF(13>=INPUTS!$B$32,"",N16)) | I17: =IF(INPUTS!$B$32=0,"",IF(13>=INPUTS!$B$32,"",MIN(E17,F17))) | J17: =IF(INPUTS!$B$32=0,"",IF(13>=INPUTS!$B$32,"",MIN(E17-I17,G17))) | K17: =IF(INPUTS!$B$32=0,"",IF(13>=INPUTS!$B$32,"",MIN(E17-I17-J17,H17))) | L17: =IF(INPUTS!$B$32=0,"",IF(13>=INPUTS!$B$32,"",(F17-I17)*(1+INPUTS!$B$28))) | M17: =IF(INPUTS!$B$32=0,"",IF(13>=INPUTS!$B$32,"",(G17-J17)*(1+INPUTS!$B$28))) | N17: =IF(INPUTS!$B$32=0,"",IF(13>=INPUTS!$B$32,"",(H17-K17)*(1+INPUTS!$B$28))) | O17: =IF(INPUTS!$B$32=0,"",IF(13>=INPUTS!$B$32,"",L17+M17+N17))
A18: =IF(INPUTS!$B$32=0,"",IF(14>=INPUTS!$B$32,"",INPUTS!$B$12+(INPUTS!$B$6-INPUTS!$B$5)+14)) | B18: =IF(INPUTS!$B$32=0,"",IF(14>=INPUTS!$B$32,"",INPUTS!$B$6+14)) | C18: =IF(INPUTS!$B$32=0,"",IF(14>=INPUTS!$B$32,"",INPUTS!$B$22*(1+INPUTS!$B$23)^(INPUTS!$B$6-INPUTS!$B$5+14))) | D18: =IF(INPUTS!$B$32=0,"",IF(14>=INPUTS!$B$32,"",INPUTS!$B$24)) | E18: =IF(INPUTS!$B$32=0,"",IF(14>=INPUTS!$B$32,"",MAX(0,C18-D18))) | F18: =IF(INPUTS!$B$32=0,"",IF(14>=INPUTS!$B$32,"",L17)) | G18: =IF(INPUTS!$B$32=0,"",IF(14>=INPUTS!$B$32,"",M17)) | H18: =IF(INPUTS!$B$32=0,"",IF(14>=INPUTS!$B$32,"",N17)) | I18: =IF(INPUTS!$B$32=0,"",IF(14>=INPUTS!$B$32,"",MIN(E18,F18))) | J18: =IF(INPUTS!$B$32=0,"",IF(14>=INPUTS!$B$32,"",MIN(E18-I18,G18))) | K18: =IF(INPUTS!$B$32=0,"",IF(14>=INPUTS!$B$32,"",MIN(E18-I18-J18,H18))) | L18: =IF(INPUTS!$B$32=0,"",IF(14>=INPUTS!$B$32,"",(F18-I18)*(1+INPUTS!$B$28))) | M18: =IF(INPUTS!$B$32=0,"",IF(14>=INPUTS!$B$32,"",(G18-J18)*(1+INPUTS!$B$28))) | N18: =IF(INPUTS!$B$32=0,"",IF(14>=INPUTS!$B$32,"",(H18-K18)*(1+INPUTS!$B$28))) | O18: =IF(INPUTS!$B$32=0,"",IF(14>=INPUTS!$B$32,"",L18+M18+N18))
A19: =IF(INPUTS!$B$32=0,"",IF(15>=INPUTS!$B$32,"",INPUTS!$B$12+(INPUTS!$B$6-INPUTS!$B$5)+15)) | B19: =IF(INPUTS!$B$32=0,"",IF(15>=INPUTS!$B$32,"",INPUTS!$B$6+15)) | C19: =IF(INPUTS!$B$32=0,"",IF(15>=INPUTS!$B$32,"",INPUTS!$B$22*(1+INPUTS!$B$23)^(INPUTS!$B$6-INPUTS!$B$5+15))) | D19: =IF(INPUTS!$B$32=0,"",IF(15>=INPUTS!$B$32,"",INPUTS!$B$24)) | E19: =IF(INPUTS!$B$32=0,"",IF(15>=INPUTS!$B$32,"",MAX(0,C19-D19))) | F19: =IF(INPUTS!$B$32=0,"",IF(15>=INPUTS!$B$32,"",L18)) | G19: =IF(INPUTS!$B$32=0,"",IF(15>=INPUTS!$B$32,"",M18)) | H19: =IF(INPUTS!$B$32=0,"",IF(15>=INPUTS!$B$32,"",N18)) | I19: =IF(INPUTS!$B$32=0,"",IF(15>=INPUTS!$B$32,"",MIN(E19,F19))) | J19: =IF(INPUTS!$B$32=0,"",IF(15>=INPUTS!$B$32,"",MIN(E19-I19,G19))) | K19: =IF(INPUTS!$B$32=0,"",IF(15>=INPUTS!$B$32,"",MIN(E19-I19-J19,H19))) | L19: =IF(INPUTS!$B$32=0,"",IF(15>=INPUTS!$B$32,"",(F19-I19)*(1+INPUTS!$B$28))) | M19: =IF(INPUTS!$B$32=0,"",IF(15>=INPUTS!$B$32,"",(G19-J19)*(1+INPUTS!$B$28))) | N19: =IF(INPUTS!$B$32=0,"",IF(15>=INPUTS!$B$32,"",(H19-K19)*(1+INPUTS!$B$28))) | O19: =IF(INPUTS!$B$32=0,"",IF(15>=INPUTS!$B$32,"",L19+M19+N19))
A20: =IF(INPUTS!$B$32=0,"",IF(16>=INPUTS!$B$32,"",INPUTS!$B$12+(INPUTS!$B$6-INPUTS!$B$5)+16)) | B20: =IF(INPUTS!$B$32=0,"",IF(16>=INPUTS!$B$32,"",INPUTS!$B$6+16)) | C20: =IF(INPUTS!$B$32=0,"",IF(16>=INPUTS!$B$32,"",INPUTS!$B$22*(1+INPUTS!$B$23)^(INPUTS!$B$6-INPUTS!$B$5+16))) | D20: =IF(INPUTS!$B$32=0,"",IF(16>=INPUTS!$B$32,"",INPUTS!$B$24)) | E20: =IF(INPUTS!$B$32=0,"",IF(16>=INPUTS!$B$32,"",MAX(0,C20-D20))) | F20: =IF(INPUTS!$B$32=0,"",IF(16>=INPUTS!$B$32,"",L19)) | G20: =IF(INPUTS!$B$32=0,"",IF(16>=INPUTS!$B$32,"",M19)) | H20: =IF(INPUTS!$B$32=0,"",IF(16>=INPUTS!$B$32,"",N19)) | I20: =IF(INPUTS!$B$32=0,"",IF(16>=INPUTS!$B$32,"",MIN(E20,F20))) | J20: =IF(INPUTS!$B$32=0,"",IF(16>=INPUTS!$B$32,"",MIN(E20-I20,G20))) | K20: =IF(INPUTS!$B$32=0,"",IF(16>=INPUTS!$B$32,"",MIN(E20-I20-J20,H20))) | L20: =IF(INPUTS!$B$32=0,"",IF(16>=INPUTS!$B$32,"",(F20-I20)*(1+INPUTS!$B$28))) | M20: =IF(INPUTS!$B$32=0,"",IF(16>=INPUTS!$B$32,"",(G20-J20)*(1+INPUTS!$B$28))) | N20: =IF(INPUTS!$B$32=0,"",IF(16>=INPUTS!$B$32,"",(H20-K20)*(1+INPUTS!$B$28))) | O20: =IF(INPUTS!$B$32=0,"",IF(16>=INPUTS!$B$32,"",L20+M20+N20))
A21: =IF(INPUTS!$B$32=0,"",IF(17>=INPUTS!$B$32,"",INPUTS!$B$12+(INPUTS!$B$6-INPUTS!$B$5)+17)) | B21: =IF(INPUTS!$B$32=0,"",IF(17>=INPUTS!$B$32,"",INPUTS!$B$6+17)) | C21: =IF(INPUTS!$B$32=0,"",IF(17>=INPUTS!$B$32,"",INPUTS!$B$22*(1+INPUTS!$B$23)^(INPUTS!$B$6-INPUTS!$B$5+17))) | D21: =IF(INPUTS!$B$32=0,"",IF(17>=INPUTS!$B$32,"",INPUTS!$B$24)) | E21: =IF(INPUTS!$B$32=0,"",IF(17>=INPUTS!$B$32,"",MAX(0,C21-D21))) | F21: =IF(INPUTS!$B$32=0,"",IF(17>=INPUTS!$B$32,"",L20)) | G21: =IF(INPUTS!$B$32=0,"",IF(17>=INPUTS!$B$32,"",M20)) | H21: =IF(INPUTS!$B$32=0,"",IF(17>=INPUTS!$B$32,"",N20)) | I21: =IF(INPUTS!$B$32=0,"",IF(17>=INPUTS!$B$32,"",MIN(E21,F21))) | J21: =IF(INPUTS!$B$32=0,"",IF(17>=INPUTS!$B$32,"",MIN(E21-I21,G21))) | K21: =IF(INPUTS!$B$32=0,"",IF(17>=INPUTS!$B$32,"",MIN(E21-I21-J21,H21))) | L21: =IF(INPUTS!$B$32=0,"",IF(17>=INPUTS!$B$32,"",(F21-I21)*(1+INPUTS!$B$28))) | M21: =IF(INPUTS!$B$32=0,"",IF(17>=INPUTS!$B$32,"",(G21-J21)*(1+INPUTS!$B$28))) | N21: =IF(INPUTS!$B$32=0,"",IF(17>=INPUTS!$B$32,"",(H21-K21)*(1+INPUTS!$B$28))) | O21: =IF(INPUTS!$B$32=0,"",IF(17>=INPUTS!$B$32,"",L21+M21+N21))
A22: =IF(INPUTS!$B$32=0,"",IF(18>=INPUTS!$B$32,"",INPUTS!$B$12+(INPUTS!$B$6-INPUTS!$B$5)+18)) | B22: =IF(INPUTS!$B$32=0,"",IF(18>=INPUTS!$B$32,"",INPUTS!$B$6+18)) | C22: =IF(INPUTS!$B$32=0,"",IF(18>=INPUTS!$B$32,"",INPUTS!$B$22*(1+INPUTS!$B$23)^(INPUTS!$B$6-INPUTS!$B$5+18))) | D22: =IF(INPUTS!$B$32=0,"",IF(18>=INPUTS!$B$32,"",INPUTS!$B$24)) | E22: =IF(INPUTS!$B$32=0,"",IF(18>=INPUTS!$B$32,"",MAX(0,C22-D22))) | F22: =IF(INPUTS!$B$32=0,"",IF(18>=INPUTS!$B$32,"",L21)) | G22: =IF(INPUTS!$B$32=0,"",IF(18>=INPUTS!$B$32,"",M21)) | H22: =IF(INPUTS!$B$32=0,"",IF(18>=INPUTS!$B$32,"",N21)) | I22: =IF(INPUTS!$B$32=0,"",IF(18>=INPUTS!$B$32,"",MIN(E22,F22))) | J22: =IF(INPUTS!$B$32=0,"",IF(18>=INPUTS!$B$32,"",MIN(E22-I22,G22))) | K22: =IF(INPUTS!$B$32=0,"",IF(18>=INPUTS!$B$32,"",MIN(E22-I22-J22,H22))) | L22: =IF(INPUTS!$B$32=0,"",IF(18>=INPUTS!$B$32,"",(F22-I22)*(1+INPUTS!$B$28))) | M22: =IF(INPUTS!$B$32=0,"",IF(18>=INPUTS!$B$32,"",(G22-J22)*(1+INPUTS!$B$28))) | N22: =IF(INPUTS!$B$32=0,"",IF(18>=INPUTS!$B$32,"",(H22-K22)*(1+INPUTS!$B$28))) | O22: =IF(INPUTS!$B$32=0,"",IF(18>=INPUTS!$B$32,"",L22+M22+N22))
A23: =IF(INPUTS!$B$32=0,"",IF(19>=INPUTS!$B$32,"",INPUTS!$B$12+(INPUTS!$B$6-INPUTS!$B$5)+19)) | B23: =IF(INPUTS!$B$32=0,"",IF(19>=INPUTS!$B$32,"",INPUTS!$B$6+19)) | C23: =IF(INPUTS!$B$32=0,"",IF(19>=INPUTS!$B$32,"",INPUTS!$B$22*(1+INPUTS!$B$23)^(INPUTS!$B$6-INPUTS!$B$5+19))) | D23: =IF(INPUTS!$B$32=0,"",IF(19>=INPUTS!$B$32,"",INPUTS!$B$24)) | E23: =IF(INPUTS!$B$32=0,"",IF(19>=INPUTS!$B$32,"",MAX(0,C23-D23))) | F23: =IF(INPUTS!$B$32=0,"",IF(19>=INPUTS!$B$32,"",L22)) | G23: =IF(INPUTS!$B$32=0,"",IF(19>=INPUTS!$B$32,"",M22)) | H23: =IF(INPUTS!$B$32=0,"",IF(19>=INPUTS!$B$32,"",N22)) | I23: =IF(INPUTS!$B$32=0,"",IF(19>=INPUTS!$B$32,"",MIN(E23,F23))) | J23: =IF(INPUTS!$B$32=0,"",IF(19>=INPUTS!$B$32,"",MIN(E23-I23,G23))) | K23: =IF(INPUTS!$B$32=0,"",IF(19>=INPUTS!$B$32,"",MIN(E23-I23-J23,H23))) | L23: =IF(INPUTS!$B$32=0,"",IF(19>=INPUTS!$B$32,"",(F23-I23)*(1+INPUTS!$B$28))) | M23: =IF(INPUTS!$B$32=0,"",IF(19>=INPUTS!$B$32,"",(G23-J23)*(1+INPUTS!$B$28))) | N23: =IF(INPUTS!$B$32=0,"",IF(19>=INPUTS!$B$32,"",(H23-K23)*(1+INPUTS!$B$28))) | O23: =IF(INPUTS!$B$32=0,"",IF(19>=INPUTS!$B$32,"",L23+M23+N23))
A24: =IF(INPUTS!$B$32=0,"",IF(20>=INPUTS!$B$32,"",INPUTS!$B$12+(INPUTS!$B$6-INPUTS!$B$5)+20)) | B24: =IF(INPUTS!$B$32=0,"",IF(20>=INPUTS!$B$32,"",INPUTS!$B$6+20)) | C24: =IF(INPUTS!$B$32=0,"",IF(20>=INPUTS!$B$32,"",INPUTS!$B$22*(1+INPUTS!$B$23)^(INPUTS!$B$6-INPUTS!$B$5+20))) | D24: =IF(INPUTS!$B$32=0,"",IF(20>=INPUTS!$B$32,"",INPUTS!$B$24)) | E24: =IF(INPUTS!$B$32=0,"",IF(20>=INPUTS!$B$32,"",MAX(0,C24-D24))) | F24: =IF(INPUTS!$B$32=0,"",IF(20>=INPUTS!$B$32,"",L23)) | G24: =IF(INPUTS!$B$32=0,"",IF(20>=INPUTS!$B$32,"",M23)) | H24: =IF(INPUTS!$B$32=0,"",IF(20>=INPUTS!$B$32,"",N23)) | I24: =IF(INPUTS!$B$32=0,"",IF(20>=INPUTS!$B$32,"",MIN(E24,F24))) | J24: =IF(INPUTS!$B$32=0,"",IF(20>=INPUTS!$B$32,"",MIN(E24-I24,G24))) | K24: =IF(INPUTS!$B$32=0,"",IF(20>=INPUTS!$B$32,"",MIN(E24-I24-J24,H24))) | L24: =IF(INPUTS!$B$32=0,"",IF(20>=INPUTS!$B$32,"",(F24-I24)*(1+INPUTS!$B$28))) | M24: =IF(INPUTS!$B$32=0,"",IF(20>=INPUTS!$B$32,"",(G24-J24)*(1+INPUTS!$B$28))) | N24: =IF(INPUTS!$B$32=0,"",IF(20>=INPUTS!$B$32,"",(H24-K24)*(1+INPUTS!$B$28))) | O24: =IF(INPUTS!$B$32=0,"",IF(20>=INPUTS!$B$32,"",L24+M24+N24))
A25: =IF(INPUTS!$B$32=0,"",IF(21>=INPUTS!$B$32,"",INPUTS!$B$12+(INPUTS!$B$6-INPUTS!$B$5)+21)) | B25: =IF(INPUTS!$B$32=0,"",IF(21>=INPUTS!$B$32,"",INPUTS!$B$6+21)) | C25: =IF(INPUTS!$B$32=0,"",IF(21>=INPUTS!$B$32,"",INPUTS!$B$22*(1+INPUTS!$B$23)^(INPUTS!$B$6-INPUTS!$B$5+21))) | D25: =IF(INPUTS!$B$32=0,"",IF(21>=INPUTS!$B$32,"",INPUTS!$B$24)) | E25: =IF(INPUTS!$B$32=0,"",IF(21>=INPUTS!$B$32,"",MAX(0,C25-D25))) | F25: =IF(INPUTS!$B$32=0,"",IF(21>=INPUTS!$B$32,"",L24)) | G25: =IF(INPUTS!$B$32=0,"",IF(21>=INPUTS!$B$32,"",M24)) | H25: =IF(INPUTS!$B$32=0,"",IF(21>=INPUTS!$B$32,"",N24)) | I25: =IF(INPUTS!$B$32=0,"",IF(21>=INPUTS!$B$32,"",MIN(E25,F25))) | J25: =IF(INPUTS!$B$32=0,"",IF(21>=INPUTS!$B$32,"",MIN(E25-I25,G25))) | K25: =IF(INPUTS!$B$32=0,"",IF(21>=INPUTS!$B$32,"",MIN(E25-I25-J25,H25))) | L25: =IF(INPUTS!$B$32=0,"",IF(21>=INPUTS!$B$32,"",(F25-I25)*(1+INPUTS!$B$28))) | M25: =IF(INPUTS!$B$32=0,"",IF(21>=INPUTS!$B$32,"",(G25-J25)*(1+INPUTS!$B$28))) | N25: =IF(INPUTS!$B$32=0,"",IF(21>=INPUTS!$B$32,"",(H25-K25)*(1+INPUTS!$B$28))) | O25: =IF(INPUTS!$B$32=0,"",IF(21>=INPUTS!$B$32,"",L25+M25+N25))
A26: =IF(INPUTS!$B$32=0,"",IF(22>=INPUTS!$B$32,"",INPUTS!$B$12+(INPUTS!$B$6-INPUTS!$B$5)+22)) | B26: =IF(INPUTS!$B$32=0,"",IF(22>=INPUTS!$B$32,"",INPUTS!$B$6+22)) | C26: =IF(INPUTS!$B$32=0,"",IF(22>=INPUTS!$B$32,"",INPUTS!$B$22*(1+INPUTS!$B$23)^(INPUTS!$B$6-INPUTS!$B$5+22))) | D26: =IF(INPUTS!$B$32=0,"",IF(22>=INPUTS!$B$32,"",INPUTS!$B$24)) | E26: =IF(INPUTS!$B$32=0,"",IF(22>=INPUTS!$B$32,"",MAX(0,C26-D26))) | F26: =IF(INPUTS!$B$32=0,"",IF(22>=INPUTS!$B$32,"",L25)) | G26: =IF(INPUTS!$B$32=0,"",IF(22>=INPUTS!$B$32,"",M25)) | H26: =IF(INPUTS!$B$32=0,"",IF(22>=INPUTS!$B$32,"",N25)) | I26: =IF(INPUTS!$B$32=0,"",IF(22>=INPUTS!$B$32,"",MIN(E26,F26))) | J26: =IF(INPUTS!$B$32=0,"",IF(22>=INPUTS!$B$32,"",MIN(E26-I26,G26))) | K26: =IF(INPUTS!$B$32=0,"",IF(22>=INPUTS!$B$32,"",MIN(E26-I26-J26,H26))) | L26: =IF(INPUTS!$B$32=0,"",IF(22>=INPUTS!$B$32,"",(F26-I26)*(1+INPUTS!$B$28))) | M26: =IF(INPUTS!$B$32=0,"",IF(22>=INPUTS!$B$32,"",(G26-J26)*(1+INPUTS!$B$28))) | N26: =IF(INPUTS!$B$32=0,"",IF(22>=INPUTS!$B$32,"",(H26-K26)*(1+INPUTS!$B$28))) | O26: =IF(INPUTS!$B$32=0,"",IF(22>=INPUTS!$B$32,"",L26+M26+N26))
A27: =IF(INPUTS!$B$32=0,"",IF(23>=INPUTS!$B$32,"",INPUTS!$B$12+(INPUTS!$B$6-INPUTS!$B$5)+23)) | B27: =IF(INPUTS!$B$32=0,"",IF(23>=INPUTS!$B$32,"",INPUTS!$B$6+23)) | C27: =IF(INPUTS!$B$32=0,"",IF(23>=INPUTS!$B$32,"",INPUTS!$B$22*(1+INPUTS!$B$23)^(INPUTS!$B$6-INPUTS!$B$5+23))) | D27: =IF(INPUTS!$B$32=0,"",IF(23>=INPUTS!$B$32,"",INPUTS!$B$24)) | E27: =IF(INPUTS!$B$32=0,"",IF(23>=INPUTS!$B$32,"",MAX(0,C27-D27))) | F27: =IF(INPUTS!$B$32=0,"",IF(23>=INPUTS!$B$32,"",L26)) | G27: =IF(INPUTS!$B$32=0,"",IF(23>=INPUTS!$B$32,"",M26)) | H27: =IF(INPUTS!$B$32=0,"",IF(23>=INPUTS!$B$32,"",N26)) | I27: =IF(INPUTS!$B$32=0,"",IF(23>=INPUTS!$B$32,"",MIN(E27,F27))) | J27: =IF(INPUTS!$B$32=0,"",IF(23>=INPUTS!$B$32,"",MIN(E27-I27,G27))) | K27: =IF(INPUTS!$B$32=0,"",IF(23>=INPUTS!$B$32,"",MIN(E27-I27-J27,H27))) | L27: =IF(INPUTS!$B$32=0,"",IF(23>=INPUTS!$B$32,"",(F27-I27)*(1+INPUTS!$B$28))) | M27: =IF(INPUTS!$B$32=0,"",IF(23>=INPUTS!$B$32,"",(G27-J27)*(1+INPUTS!$B$28))) | N27: =IF(INPUTS!$B$32=0,"",IF(23>=INPUTS!$B$32,"",(H27-K27)*(1+INPUTS!$B$28))) | O27: =IF(INPUTS!$B$32=0,"",IF(23>=INPUTS!$B$32,"",L27+M27+N27))
A28: =IF(INPUTS!$B$32=0,"",IF(24>=INPUTS!$B$32,"",INPUTS!$B$12+(INPUTS!$B$6-INPUTS!$B$5)+24)) | B28: =IF(INPUTS!$B$32=0,"",IF(24>=INPUTS!$B$32,"",INPUTS!$B$6+24)) | C28: =IF(INPUTS!$B$32=0,"",IF(24>=INPUTS!$B$32,"",INPUTS!$B$22*(1+INPUTS!$B$23)^(INPUTS!$B$6-INPUTS!$B$5+24))) | D28: =IF(INPUTS!$B$32=0,"",IF(24>=INPUTS!$B$32,"",INPUTS!$B$24)) | E28: =IF(INPUTS!$B$32=0,"",IF(24>=INPUTS!$B$32,"",MAX(0,C28-D28))) | F28: =IF(INPUTS!$B$32=0,"",IF(24>=INPUTS!$B$32,"",L27)) | G28: =IF(INPUTS!$B$32=0,"",IF(24>=INPUTS!$B$32,"",M27)) | H28: =IF(INPUTS!$B$32=0,"",IF(24>=INPUTS!$B$32,"",N27)) | I28: =IF(INPUTS!$B$32=0,"",IF(24>=INPUTS!$B$32,"",MIN(E28,F28))) | J28: =IF(INPUTS!$B$32=0,"",IF(24>=INPUTS!$B$32,"",MIN(E28-I28,G28))) | K28: =IF(INPUTS!$B$32=0,"",IF(24>=INPUTS!$B$32,"",MIN(E28-I28-J28,H28))) | L28: =IF(INPUTS!$B$32=0,"",IF(24>=INPUTS!$B$32,"",(F28-I28)*(1+INPUTS!$B$28))) | M28: =IF(INPUTS!$B$32=0,"",IF(24>=INPUTS!$B$32,"",(G28-J28)*(1+INPUTS!$B$28))) | N28: =IF(INPUTS!$B$32=0,"",IF(24>=INPUTS!$B$32,"",(H28-K28)*(1+INPUTS!$B$28))) | O28: =IF(INPUTS!$B$32=0,"",IF(24>=INPUTS!$B$32,"",L28+M28+N28))
A30: END OF BRIDGE → | C30: =IF(INPUTS!$B$32=0,INPUTS!$B$22,IFERROR(LOOKUP(9.99E+307,C4:C28),INPUTS!$B$22)) -> 65377.716 | L30: =IF(INPUTS!$B$32=0,(INPUTS!$B$15+INPUTS!$B$18)*(1+INPUTS!$B$28)^MAX(0,INPUTS!$B$6-INPUTS!$B$5),IFERROR(LOOKUP(9.99E+307,L4:L28),(INPUTS!$B$15+INPUTS!$B$18)*(1+INPUTS!$B$28)^MAX(0,INPUTS!$B$6-INPUTS!$B$5))) -> 326984 | M30: =IF(INPUTS!$B$32=0,INPUTS!$B$17*(1+INPUTS!$B$28)^MAX(0,INPUTS!$B$6-INPUTS!$B$5),IFERROR(LOOKUP(9.99E+307,M4:M28),INPUTS!$B$17*(1+INPUTS!$B$28)^MAX(0,INPUTS!$B$6-INPUTS!$B$5))) -> 248249.35 | N30: =IF(INPUTS!$B$32=0,INPUTS!$B$16*(1+INPUTS!$B$28)^MAX(0,INPUTS!$B$6-INPUTS!$B$5),IFERROR(LOOKUP(9.99E+307,N4:N28),INPUTS!$B$16*(1+INPUTS!$B$28)^MAX(0,INPUTS!$B$6-INPUTS!$B$5))) -> 1075747.2

Sheet TAX ESTIMATE
A1: FEDERAL TAX ESTIMATE · Bridge Years
A2: =IF(INPUTS!B9="MFJ","Using 2026 MFJ brackets + $32,200 standard deduction.","Using 2026 Single brackets + $16,100 standard deduction.") -> Using 2026 MFJ brackets + $32,200 standard deduction.
A4: 2026 BRACKETS (auto-switch via INPUTS Filing Status)
A5: Rate | B5: From | C5: To | D5: RateΔ
A6: 0.1 | B6: =IF(INPUTS!$B$9="MFJ",0,0) -> 0 | C6: =IF(INPUTS!$B$9="MFJ",24800,12400) -> 24800 | D6: 0.1
A7: 0.12 | B7: =IF(INPUTS!$B$9="MFJ",24800,12400) -> 24800 | C7: =IF(INPUTS!$B$9="MFJ",100800,50400) -> 100800 | D7: 0.02
A8: 0.22 | B8: =IF(INPUTS!$B$9="MFJ",100800,50400) -> 100800 | C8: =IF(INPUTS!$B$9="MFJ",211400,105700) -> 211400 | D8: 0.1
A9: 0.24 | B9: =IF(INPUTS!$B$9="MFJ",211400,105700) -> 211400 | C9: =IF(INPUTS!$B$9="MFJ",403550,201775) -> 403550 | D9: 0.02
A10: 0.32 | B10: =IF(INPUTS!$B$9="MFJ",403550,201775) -> 403550 | C10: =IF(INPUTS!$B$9="MFJ",512450,256225) -> 512450 | D10: 0.08
A11: 0.35 | B11: =IF(INPUTS!$B$9="MFJ",512450,256225) -> 512450 | C11: =IF(INPUTS!$B$9="MFJ",768700,640600) -> 768700 | D11: 0.03
A12: 0.37 | B12: =IF(INPUTS!$B$9="MFJ",768700,640600) -> 768700 | C12: =IF(INPUTS!$B$9="MFJ",99999999,99999999) -> 99999999 | D12: 0.02
A13: Source: IRS Rev. Proc. 2025-32 (2026 inflation adjustments). Update annually.
A14: ESTIMATED TAX BY BRIDGE YEAR
A16: Year | B16: Income (401k + conv. + other) | C16: Std Deduction | D16: Taxable Income | E16: Fed Tax | F16: State Tax | G16: Note
A17: =IF(BRIDGE!A4="","",BRIDGE!A4) -> 2029 | B17: =IF(A17="","",BRIDGE!K4+'ROTH LADDER'!D6+INPUTS!$B$24) -> 84600 | C17: =IF(A17="","",INPUTS!$B$34) -> 32200 | D17: =IF(A17="","",MAX(0,B17-C17)) -> 52400 | E17: =IF(A17="","",SUMPRODUCT(((D17-$B$6:$B$12)>0)*(D17-$B$6:$B$12)*$D$6:$D$12)) -> 5792 | F17: =IF(A17="","",D17*INPUTS!$B$11) -> 0 | G17: =IF(A17="","",IF(D17=0,"No federal tax",IF(D17<=$C$7,"Inside 12% bracket","⚠ Above 12% bracket"))) -> Inside 12% bracket
A18: =IF(BRIDGE!A5="","",BRIDGE!A5) -> 2030 | B18: =IF(A18="","",BRIDGE!K5+'ROTH LADDER'!D7+INPUTS!$B$24) -> 84600 | C18: =IF(A18="","",INPUTS!$B$34) -> 32200 | D18: =IF(A18="","",MAX(0,B18-C18)) -> 52400 | E18: =IF(A18="","",SUMPRODUCT(((D18-$B$6:$B$12)>0)*(D18-$B$6:$B$12)*$D$6:$D$12)) -> 5792 | F18: =IF(A18="","",D18*INPUTS!$B$11) -> 0 | G18: =IF(A18="","",IF(D18=0,"No federal tax",IF(D18<=$C$7,"Inside 12% bracket","⚠ Above 12% bracket"))) -> Inside 12% bracket
A19: =IF(BRIDGE!A6="","",BRIDGE!A6) -> 2031 | B19: =IF(A19="","",BRIDGE!K6+'ROTH LADDER'!D8+INPUTS!$B$24) -> 84600 | C19: =IF(A19="","",INPUTS!$B$34) -> 32200 | D19: =IF(A19="","",MAX(0,B19-C19)) -> 52400 | E19: =IF(A19="","",SUMPRODUCT(((D19-$B$6:$B$12)>0)*(D19-$B$6:$B$12)*$D$6:$D$12)) -> 5792 | F19: =IF(A19="","",D19*INPUTS!$B$11) -> 0 | G19: =IF(A19="","",IF(D19=0,"No federal tax",IF(D19<=$C$7,"Inside 12% bracket","⚠ Above 12% bracket"))) -> Inside 12% bracket
A20: =IF(BRIDGE!A7="","",BRIDGE!A7) -> 2032 | B20: =IF(A20="","",BRIDGE!K7+'ROTH LADDER'!D9+INPUTS!$B$24) -> 84600 | C20: =IF(A20="","",INPUTS!$B$34) -> 32200 | D20: =IF(A20="","",MAX(0,B20-C20)) -> 52400 | E20: =IF(A20="","",SUMPRODUCT(((D20-$B$6:$B$12)>0)*(D20-$B$6:$B$12)*$D$6:$D$12)) -> 5792 | F20: =IF(A20="","",D20*INPUTS!$B$11) -> 0 | G20: =IF(A20="","",IF(D20=0,"No federal tax",IF(D20<=$C$7,"Inside 12% bracket","⚠ Above 12% bracket"))) -> Inside 12% bracket
A21: =IF(BRIDGE!A8="","",BRIDGE!A8) -> 2033 | B21: =IF(A21="","",BRIDGE!K8+'ROTH LADDER'!D10+INPUTS!$B$24) -> 84600 | C21: =IF(A21="","",INPUTS!$B$34) -> 32200 | D21: =IF(A21="","",MAX(0,B21-C21)) -> 52400 | E21: =IF(A21="","",SUMPRODUCT(((D21-$B$6:$B$12)>0)*(D21-$B$6:$B$12)*$D$6:$D$12)) -> 5792 | F21: =IF(A21="","",D21*INPUTS!$B$11) -> 0 | G21: =IF(A21="","",IF(D21=0,"No federal tax",IF(D21<=$C$7,"Inside 12% bracket","⚠ Above 12% bracket"))) -> Inside 12% bracket
A22: =IF(BRIDGE!A9="","",BRIDGE!A9) | B22: =IF(A22="","",BRIDGE!K9+'ROTH LADDER'!D11+INPUTS!$B$24) | C22: =IF(A22="","",INPUTS!$B$34) | D22: =IF(A22="","",MAX(0,B22-C22)) | E22: =IF(A22="","",SUMPRODUCT(((D22-$B$6:$B$12)>0)*(D22-$B$6:$B$12)*$D$6:$D$12)) | F22: =IF(A22="","",D22*INPUTS!$B$11) | G22: =IF(A22="","",IF(D22=0,"No federal tax",IF(D22<=$C$7,"Inside 12% bracket","⚠ Above 12% bracket")))
A23: =IF(BRIDGE!A10="","",BRIDGE!A10) | B23: =IF(A23="","",BRIDGE!K10+'ROTH LADDER'!D12+INPUTS!$B$24) | C23: =IF(A23="","",INPUTS!$B$34) | D23: =IF(A23="","",MAX(0,B23-C23)) | E23: =IF(A23="","",SUMPRODUCT(((D23-$B$6:$B$12)>0)*(D23-$B$6:$B$12)*$D$6:$D$12)) | F23: =IF(A23="","",D23*INPUTS!$B$11) | G23: =IF(A23="","",IF(D23=0,"No federal tax",IF(D23<=$C$7,"Inside 12% bracket","⚠ Above 12% bracket")))
A24: =IF(BRIDGE!A11="","",BRIDGE!A11) | B24: =IF(A24="","",BRIDGE!K11+'ROTH LADDER'!D13+INPUTS!$B$24) | C24: =IF(A24="","",INPUTS!$B$34) | D24: =IF(A24="","",MAX(0,B24-C24)) | E24: =IF(A24="","",SUMPRODUCT(((D24-$B$6:$B$12)>0)*(D24-$B$6:$B$12)*$D$6:$D$12)) | F24: =IF(A24="","",D24*INPUTS!$B$11) | G24: =IF(A24="","",IF(D24=0,"No federal tax",IF(D24<=$C$7,"Inside 12% bracket","⚠ Above 12% bracket")))
A25: =IF(BRIDGE!A12="","",BRIDGE!A12) | B25: =IF(A25="","",BRIDGE!K12+'ROTH LADDER'!D14+INPUTS!$B$24) | C25: =IF(A25="","",INPUTS!$B$34) | D25: =IF(A25="","",MAX(0,B25-C25)) | E25: =IF(A25="","",SUMPRODUCT(((D25-$B$6:$B$12)>0)*(D25-$B$6:$B$12)*$D$6:$D$12)) | F25: =IF(A25="","",D25*INPUTS!$B$11) | G25: =IF(A25="","",IF(D25=0,"No federal tax",IF(D25<=$C$7,"Inside 12% bracket","⚠ Above 12% bracket")))
A26: =IF(BRIDGE!A13="","",BRIDGE!A13) | B26: =IF(A26="","",BRIDGE!K13+'ROTH LADDER'!D15+INPUTS!$B$24) | C26: =IF(A26="","",INPUTS!$B$34) | D26: =IF(A26="","",MAX(0,B26-C26)) | E26: =IF(A26="","",SUMPRODUCT(((D26-$B$6:$B$12)>0)*(D26-$B$6:$B$12)*$D$6:$D$12)) | F26: =IF(A26="","",D26*INPUTS!$B$11) | G26: =IF(A26="","",IF(D26=0,"No federal tax",IF(D26<=$C$7,"Inside 12% bracket","⚠ Above 12% bracket")))
A27: =IF(BRIDGE!A14="","",BRIDGE!A14) | B27: =IF(A27="","",BRIDGE!K14+'ROTH LADDER'!D16+INPUTS!$B$24) | C27: =IF(A27="","",INPUTS!$B$34) | D27: =IF(A27="","",MAX(0,B27-C27)) | E27: =IF(A27="","",SUMPRODUCT(((D27-$B$6:$B$12)>0)*(D27-$B$6:$B$12)*$D$6:$D$12)) | F27: =IF(A27="","",D27*INPUTS!$B$11) | G27: =IF(A27="","",IF(D27=0,"No federal tax",IF(D27<=$C$7,"Inside 12% bracket","⚠ Above 12% bracket")))
A28: =IF(BRIDGE!A15="","",BRIDGE!A15) | B28: =IF(A28="","",BRIDGE!K15+'ROTH LADDER'!D17+INPUTS!$B$24) | C28: =IF(A28="","",INPUTS!$B$34) | D28: =IF(A28="","",MAX(0,B28-C28)) | E28: =IF(A28="","",SUMPRODUCT(((D28-$B$6:$B$12)>0)*(D28-$B$6:$B$12)*$D$6:$D$12)) | F28: =IF(A28="","",D28*INPUTS!$B$11) | G28: =IF(A28="","",IF(D28=0,"No federal tax",IF(D28<=$C$7,"Inside 12% bracket","⚠ Above 12% bracket")))
... A41: =IF(BRIDGE!A28="","",BRIDGE!A28) | B41: =IF(A41="","",BRIDGE!K28+'ROTH LADDER'!D30+INPUTS!$B$24) | C41: =IF(A41="","",INPUTS!$B$34) | D41: =IF(A41="","",MAX(0,B41-C41)) | E41: =IF(A41="","",SUMPRODUCT(((D41-$B$6:$B$12)>0)*(D41-$B$6:$B$12)*$D$6:$D$12)) | F41: =IF(A41="","",D41*INPUTS!$B$11) | G41: =IF(A41="","",IF(D41=0,"No federal tax",IF(D41<=$C$7,"Inside 12% bracket","⚠ Above 12% bracket")))

Sheet ROTH LADDER
A1: ROTH CONVERSION LADDER · 5-Year Pipeline
A2: Suggested conversion = remaining 12% bracket space after bridge income. Each rung unlocks penalty-free after 5 years.
A3: ACA WARNING: conversions count toward MAGI. The cross-check below flags any year total MAGI exceeds the est. 400% FPL cliff (~$81,760 for 2-person household, 2026).
A4: ACA 400% FPL cliff (est.) → | C4: =4*(15650+5500*(MAX(1,INPUTS!$B$26)-1)) -> 84600 | D4: =("Household of "&INPUTS!$B$26&" — 2025 HHS guideline, verify annually") -> Household of 2 — 2025 HHS guideline, verify annually
A5: Year | B5: Age | C5: 12% Bracket Room (gross) | D5: Suggested Conversion | E5: Tax on Conv. (12%) | F5: MAGI (income+conv.) | G5: ACA Cliff Check | H5: Unlocks Penalty-Free
A6: =IF(BRIDGE!A4="","",BRIDGE!A4) -> 2029 | B6: =IF(A6="","",BRIDGE!B4) -> 55 | C6: =IF(A6="","",MAX(0,'TAX ESTIMATE'!$C$7+INPUTS!$B$34-BRIDGE!K4-INPUTS!$B$24)) -> 133000 | D6: =IF(A6="","",MAX(0,MIN(C6,$C$4-BRIDGE!K4-INPUTS!$B$24))) -> 84600 | E6: =IF(A6="","",D6*0.12) -> 10152 | F6: =IF(A6="","",BRIDGE!K4+D6+INPUTS!$B$24) -> 84600 | G6: =IF(A6="","",IF(F6>$C$4,"⚠ OVER CLIFF — trims subsidy to $0","✓ Under cliff")) -> ✓ Under cliff | H6: =IF(A6="","",A6+5&" (5-yr rule)") -> 2034 (5-yr rule)
A7: =IF(BRIDGE!A5="","",BRIDGE!A5) -> 2030 | B7: =IF(A7="","",BRIDGE!B5) -> 56 | C7: =IF(A7="","",MAX(0,'TAX ESTIMATE'!$C$7+INPUTS!$B$34-BRIDGE!K5-INPUTS!$B$24)) -> 133000 | D7: =IF(A7="","",MAX(0,MIN(C7,$C$4-BRIDGE!K5-INPUTS!$B$24))) -> 84600 | E7: =IF(A7="","",D7*0.12) -> 10152 | F7: =IF(A7="","",BRIDGE!K5+D7+INPUTS!$B$24) -> 84600 | G7: =IF(A7="","",IF(F7>$C$4,"⚠ OVER CLIFF — trims subsidy to $0","✓ Under cliff")) -> ✓ Under cliff | H7: =IF(A7="","",A7+5&" (5-yr rule)") -> 2035 (5-yr rule)
A8: =IF(BRIDGE!A6="","",BRIDGE!A6) -> 2031 | B8: =IF(A8="","",BRIDGE!B6) -> 57 | C8: =IF(A8="","",MAX(0,'TAX ESTIMATE'!$C$7+INPUTS!$B$34-BRIDGE!K6-INPUTS!$B$24)) -> 133000 | D8: =IF(A8="","",MAX(0,MIN(C8,$C$4-BRIDGE!K6-INPUTS!$B$24))) -> 84600 | E8: =IF(A8="","",D8*0.12) -> 10152 | F8: =IF(A8="","",BRIDGE!K6+D8+INPUTS!$B$24) -> 84600 | G8: =IF(A8="","",IF(F8>$C$4,"⚠ OVER CLIFF — trims subsidy to $0","✓ Under cliff")) -> ✓ Under cliff | H8: =IF(A8="","",A8+5&" (5-yr rule)") -> 2036 (5-yr rule)
A9: =IF(BRIDGE!A7="","",BRIDGE!A7) -> 2032 | B9: =IF(A9="","",BRIDGE!B7) -> 58 | C9: =IF(A9="","",MAX(0,'TAX ESTIMATE'!$C$7+INPUTS!$B$34-BRIDGE!K7-INPUTS!$B$24)) -> 133000 | D9: =IF(A9="","",MAX(0,MIN(C9,$C$4-BRIDGE!K7-INPUTS!$B$24))) -> 84600 | E9: =IF(A9="","",D9*0.12) -> 10152 | F9: =IF(A9="","",BRIDGE!K7+D9+INPUTS!$B$24) -> 84600 | G9: =IF(A9="","",IF(F9>$C$4,"⚠ OVER CLIFF — trims subsidy to $0","✓ Under cliff")) -> ✓ Under cliff | H9: =IF(A9="","",A9+5&" (5-yr rule)") -> 2037 (5-yr rule)
A10: =IF(BRIDGE!A8="","",BRIDGE!A8) -> 2033 | B10: =IF(A10="","",BRIDGE!B8) -> 59 | C10: =IF(A10="","",MAX(0,'TAX ESTIMATE'!$C$7+INPUTS!$B$34-BRIDGE!K8-INPUTS!$B$24)) -> 133000 | D10: =IF(A10="","",MAX(0,MIN(C10,$C$4-BRIDGE!K8-INPUTS!$B$24))) -> 84600 | E10: =IF(A10="","",D10*0.12) -> 10152 | F10: =IF(A10="","",BRIDGE!K8+D10+INPUTS!$B$24) -> 84600 | G10: =IF(A10="","",IF(F10>$C$4,"⚠ OVER CLIFF — trims subsidy to $0","✓ Under cliff")) -> ✓ Under cliff | H10: =IF(A10="","",A10+5&" (5-yr rule)") -> 2038 (5-yr rule)
A11: =IF(BRIDGE!A9="","",BRIDGE!A9) | B11: =IF(A11="","",BRIDGE!B9) | C11: =IF(A11="","",MAX(0,'TAX ESTIMATE'!$C$7+INPUTS!$B$34-BRIDGE!K9-INPUTS!$B$24)) | D11: =IF(A11="","",MAX(0,MIN(C11,$C$4-BRIDGE!K9-INPUTS!$B$24))) | E11: =IF(A11="","",D11*0.12) | F11: =IF(A11="","",BRIDGE!K9+D11+INPUTS!$B$24) | G11: =IF(A11="","",IF(F11>$C$4,"⚠ OVER CLIFF — trims subsidy to $0","✓ Under cliff")) | H11: =IF(A11="","",A11+5&" (5-yr rule)")
A12: =IF(BRIDGE!A10="","",BRIDGE!A10) | B12: =IF(A12="","",BRIDGE!B10) | C12: =IF(A12="","",MAX(0,'TAX ESTIMATE'!$C$7+INPUTS!$B$34-BRIDGE!K10-INPUTS!$B$24)) | D12: =IF(A12="","",MAX(0,MIN(C12,$C$4-BRIDGE!K10-INPUTS!$B$24))) | E12: =IF(A12="","",D12*0.12) | F12: =IF(A12="","",BRIDGE!K10+D12+INPUTS!$B$24) | G12: =IF(A12="","",IF(F12>$C$4,"⚠ OVER CLIFF — trims subsidy to $0","✓ Under cliff")) | H12: =IF(A12="","",A12+5&" (5-yr rule)")
A13: =IF(BRIDGE!A11="","",BRIDGE!A11) | B13: =IF(A13="","",BRIDGE!B11) | C13: =IF(A13="","",MAX(0,'TAX ESTIMATE'!$C$7+INPUTS!$B$34-BRIDGE!K11-INPUTS!$B$24)) | D13: =IF(A13="","",MAX(0,MIN(C13,$C$4-BRIDGE!K11-INPUTS!$B$24))) | E13: =IF(A13="","",D13*0.12) | F13: =IF(A13="","",BRIDGE!K11+D13+INPUTS!$B$24) | G13: =IF(A13="","",IF(F13>$C$4,"⚠ OVER CLIFF — trims subsidy to $0","✓ Under cliff")) | H13: =IF(A13="","",A13+5&" (5-yr rule)")
A14: =IF(BRIDGE!A12="","",BRIDGE!A12) | B14: =IF(A14="","",BRIDGE!B12) | C14: =IF(A14="","",MAX(0,'TAX ESTIMATE'!$C$7+INPUTS!$B$34-BRIDGE!K12-INPUTS!$B$24)) | D14: =IF(A14="","",MAX(0,MIN(C14,$C$4-BRIDGE!K12-INPUTS!$B$24))) | E14: =IF(A14="","",D14*0.12) | F14: =IF(A14="","",BRIDGE!K12+D14+INPUTS!$B$24) | G14: =IF(A14="","",IF(F14>$C$4,"⚠ OVER CLIFF — trims subsidy to $0","✓ Under cliff")) | H14: =IF(A14="","",A14+5&" (5-yr rule)")
A15: =IF(BRIDGE!A13="","",BRIDGE!A13) | B15: =IF(A15="","",BRIDGE!B13) | C15: =IF(A15="","",MAX(0,'TAX ESTIMATE'!$C$7+INPUTS!$B$34-BRIDGE!K13-INPUTS!$B$24)) | D15: =IF(A15="","",MAX(0,MIN(C15,$C$4-BRIDGE!K13-INPUTS!$B$24))) | E15: =IF(A15="","",D15*0.12) | F15: =IF(A15="","",BRIDGE!K13+D15+INPUTS!$B$24) | G15: =IF(A15="","",IF(F15>$C$4,"⚠ OVER CLIFF — trims subsidy to $0","✓ Under cliff")) | H15: =IF(A15="","",A15+5&" (5-yr rule)")
A16: =IF(BRIDGE!A14="","",BRIDGE!A14) | B16: =IF(A16="","",BRIDGE!B14) | C16: =IF(A16="","",MAX(0,'TAX ESTIMATE'!$C$7+INPUTS!$B$34-BRIDGE!K14-INPUTS!$B$24)) | D16: =IF(A16="","",MAX(0,MIN(C16,$C$4-BRIDGE!K14-INPUTS!$B$24))) | E16: =IF(A16="","",D16*0.12) | F16: =IF(A16="","",BRIDGE!K14+D16+INPUTS!$B$24) | G16: =IF(A16="","",IF(F16>$C$4,"⚠ OVER CLIFF — trims subsidy to $0","✓ Under cliff")) | H16: =IF(A16="","",A16+5&" (5-yr rule)")
A17: =IF(BRIDGE!A15="","",BRIDGE!A15) | B17: =IF(A17="","",BRIDGE!B15) | C17: =IF(A17="","",MAX(0,'TAX ESTIMATE'!$C$7+INPUTS!$B$34-BRIDGE!K15-INPUTS!$B$24)) | D17: =IF(A17="","",MAX(0,MIN(C17,$C$4-BRIDGE!K15-INPUTS!$B$24))) | E17: =IF(A17="","",D17*0.12) | F17: =IF(A17="","",BRIDGE!K15+D17+INPUTS!$B$24) | G17: =IF(A17="","",IF(F17>$C$4,"⚠ OVER CLIFF — trims subsidy to $0","✓ Under cliff")) | H17: =IF(A17="","",A17+5&" (5-yr rule)")
... A30: =IF(BRIDGE!A28="","",BRIDGE!A28) | B30: =IF(A30="","",BRIDGE!B28) | C30: =IF(A30="","",MAX(0,'TAX ESTIMATE'!$C$7+INPUTS!$B$34-BRIDGE!K28-INPUTS!$B$24)) | D30: =IF(A30="","",MAX(0,MIN(C30,$C$4-BRIDGE!K28-INPUTS!$B$24))) | E30: =IF(A30="","",D30*0.12) | F30: =IF(A30="","",BRIDGE!K28+D30+INPUTS!$B$24) | G30: =IF(A30="","",IF(F30>$C$4,"⚠ OVER CLIFF — trims subsidy to $0","✓ Under cliff")) | H30: =IF(A30="","",A30+5&" (5-yr rule)")
A32: Suggested Conversion = smaller of 12% bracket space and ACA cliff headroom (cliff − 401k draws − other income). MAGI shown includes conversion + 401k + other income; taxable-account dividends/gains not modeled.

Sheet POST-59.5
A1: POST-59½ PROJECTION · To Life Expectancy
A2: 401k+Taxable draws first, Roth preserved. Starts at the later of 59½ or your retirement age. Social Security begins at your claiming age. Balances are pre-tax — 401k withdrawals are taxable, budget a 15–20% gross-up.
A4: Year | B4: Age | C4: Spending (Infl.) | D4: SS Income | E4: Other Income | F4: Net Withdrawal | G4: 401k+Taxable Bal. | H4: Roth Bal.
A5: =IF(MAX(59.5,INPUTS!$B$6)+0>INPUTS!$B$8,"",INPUTS!$B$12+(MAX(59.5,INPUTS!$B$6)-INPUTS!$B$5)+0) -> 2033.5 | B5: =IF(A5="","",MAX(59.5,INPUTS!$B$6)+0) -> 59.5 | C5: =IF(A5="","",INPUTS!$B$22*(1+INPUTS!$B$23)^(A5-INPUTS!$B$12)) -> 66189.893 | D5: =IF(A5="","",IF(B5>=INPUTS!$B$7,INPUTS!$B$25*(1+INPUTS!$B$23)^(A5-INPUTS!$B$12),0)) -> 0 | E5: =IF(A5="","",INPUTS!$B$24) -> 0 | F5: =IF(A5="","",MAX(0,C5-D5-E5)) -> 66189.893 | G5: =IF(A5="","",MAX(0,BRIDGE!L30+BRIDGE!N30-F5)*(1+INPUTS!$B$28)) -> 1423416.5 | H5: =IF(A5="","",MAX(0,BRIDGE!M30-MAX(0,F5-BRIDGE!L30-BRIDGE!N30))*(1+INPUTS!$B$28)) -> 264385.56
A6: =IF(MAX(59.5,INPUTS!$B$6)+1>INPUTS!$B$8,"",INPUTS!$B$12+(MAX(59.5,INPUTS!$B$6)-INPUTS!$B$5)+1) -> 2034.5 | B6: =IF(A6="","",MAX(59.5,INPUTS!$B$6)+1) -> 60.5 | C6: =IF(A6="","",INPUTS!$B$22*(1+INPUTS!$B$23)^(A6-INPUTS!$B$12)) -> 67844.64 | D6: =IF(A6="","",IF(B6>=INPUTS!$B$7,INPUTS!$B$25*(1+INPUTS!$B$23)^(A6-INPUTS!$B$12),0)) -> 0 | E6: =IF(A6="","",INPUTS!$B$24) -> 0 | F6: =IF(A6="","",IF(G5+H5=0,0,MAX(0,C6-D6-E6))) -> 67844.64 | G6: =IF(A6="","",MAX(0,G5-F6)*(1+INPUTS!$B$28)) -> 1443684 | H6: =IF(A6="","",MAX(0,H5-MAX(0,F6-G5))*(1+INPUTS!$B$28)) -> 281570.62
A7: =IF(MAX(59.5,INPUTS!$B$6)+2>INPUTS!$B$8,"",INPUTS!$B$12+(MAX(59.5,INPUTS!$B$6)-INPUTS!$B$5)+2) -> 2035.5 | B7: =IF(A7="","",MAX(59.5,INPUTS!$B$6)+2) -> 61.5 | C7: =IF(A7="","",INPUTS!$B$22*(1+INPUTS!$B$23)^(A7-INPUTS!$B$12)) -> 69540.756 | D7: =IF(A7="","",IF(B7>=INPUTS!$B$7,INPUTS!$B$25*(1+INPUTS!$B$23)^(A7-INPUTS!$B$12),0)) -> 0 | E7: =IF(A7="","",INPUTS!$B$24) -> 0 | F7: =IF(A7="","",IF(G6+H6=0,0,MAX(0,C7-D7-E7))) -> 69540.756 | G7: =IF(A7="","",MAX(0,G6-F7)*(1+INPUTS!$B$28)) -> 1463462.6 | H7: =IF(A7="","",MAX(0,H6-MAX(0,F7-G6))*(1+INPUTS!$B$28)) -> 299872.71
A8: =IF(MAX(59.5,INPUTS!$B$6)+3>INPUTS!$B$8,"",INPUTS!$B$12+(MAX(59.5,INPUTS!$B$6)-INPUTS!$B$5)+3) -> 2036.5 | B8: =IF(A8="","",MAX(59.5,INPUTS!$B$6)+3) -> 62.5 | C8: =IF(A8="","",INPUTS!$B$22*(1+INPUTS!$B$23)^(A8-INPUTS!$B$12)) -> 71279.275 | D8: =IF(A8="","",IF(B8>=INPUTS!$B$7,INPUTS!$B$25*(1+INPUTS!$B$23)^(A8-INPUTS!$B$12),0)) -> 0 | E8: =IF(A8="","",INPUTS!$B$24) -> 0 | F8: =IF(A8="","",IF(G7+H7=0,0,MAX(0,C8-D8-E8))) -> 71279.275 | G8: =IF(A8="","",MAX(0,G7-F8)*(1+INPUTS!$B$28)) -> 1482675.2 | H8: =IF(A8="","",MAX(0,H7-MAX(0,F8-G7))*(1+INPUTS!$B$28)) -> 319364.44
A9: =IF(MAX(59.5,INPUTS!$B$6)+4>INPUTS!$B$8,"",INPUTS!$B$12+(MAX(59.5,INPUTS!$B$6)-INPUTS!$B$5)+4) -> 2037.5 | B9: =IF(A9="","",MAX(59.5,INPUTS!$B$6)+4) -> 63.5 | C9: =IF(A9="","",INPUTS!$B$22*(1+INPUTS!$B$23)^(A9-INPUTS!$B$12)) -> 73061.257 | D9: =IF(A9="","",IF(B9>=INPUTS!$B$7,INPUTS!$B$25*(1+INPUTS!$B$23)^(A9-INPUTS!$B$12),0)) -> 0 | E9: =IF(A9="","",INPUTS!$B$24) -> 0 | F9: =IF(A9="","",IF(G8+H8=0,0,MAX(0,C9-D9-E9))) -> 73061.257 | G9: =IF(A9="","",MAX(0,G8-F9)*(1+INPUTS!$B$28)) -> 1501238.8 | H9: =IF(A9="","",MAX(0,H8-MAX(0,F9-G8))*(1+INPUTS!$B$28)) -> 340123.12
A10: =IF(MAX(59.5,INPUTS!$B$6)+5>INPUTS!$B$8,"",INPUTS!$B$12+(MAX(59.5,INPUTS!$B$6)-INPUTS!$B$5)+5) -> 2038.5 | B10: =IF(A10="","",MAX(59.5,INPUTS!$B$6)+5) -> 64.5 | C10: =IF(A10="","",INPUTS!$B$22*(1+INPUTS!$B$23)^(A10-INPUTS!$B$12)) -> 74887.789 | D10: =IF(A10="","",IF(B10>=INPUTS!$B$7,INPUTS!$B$25*(1+INPUTS!$B$23)^(A10-INPUTS!$B$12),0)) -> 0 | E10: =IF(A10="","",INPUTS!$B$24) -> 0 | F10: =IF(A10="","",IF(G9+H9=0,0,MAX(0,C10-D10-E10))) -> 74887.789 | G10: =IF(A10="","",MAX(0,G9-F10)*(1+INPUTS!$B$28)) -> 1519063.9 | H10: =IF(A10="","",MAX(0,H9-MAX(0,F10-G9))*(1+INPUTS!$B$28)) -> 362231.13
A11: =IF(MAX(59.5,INPUTS!$B$6)+6>INPUTS!$B$8,"",INPUTS!$B$12+(MAX(59.5,INPUTS!$B$6)-INPUTS!$B$5)+6) -> 2039.5 | B11: =IF(A11="","",MAX(59.5,INPUTS!$B$6)+6) -> 65.5 | C11: =IF(A11="","",INPUTS!$B$22*(1+INPUTS!$B$23)^(A11-INPUTS!$B$12)) -> 76759.983 | D11: =IF(A11="","",IF(B11>=INPUTS!$B$7,INPUTS!$B$25*(1+INPUTS!$B$23)^(A11-INPUTS!$B$12),0)) -> 0 | E11: =IF(A11="","",INPUTS!$B$24) -> 0 | F11: =IF(A11="","",IF(G10+H10=0,0,MAX(0,C11-D11-E11))) -> 76759.983 | G11: =IF(A11="","",MAX(0,G10-F11)*(1+INPUTS!$B$28)) -> 1536053.6 | H11: =IF(A11="","",MAX(0,H10-MAX(0,F11-G10))*(1+INPUTS!$B$28)) -> 385776.15
A12: =IF(MAX(59.5,INPUTS!$B$6)+7>INPUTS!$B$8,"",INPUTS!$B$12+(MAX(59.5,INPUTS!$B$6)-INPUTS!$B$5)+7) -> 2040.5 | B12: =IF(A12="","",MAX(59.5,INPUTS!$B$6)+7) -> 66.5 | C12: =IF(A12="","",INPUTS!$B$22*(1+INPUTS!$B$23)^(A12-INPUTS!$B$12)) -> 78678.983 | D12: =IF(A12="","",IF(B12>=INPUTS!$B$7,INPUTS!$B$25*(1+INPUTS!$B$23)^(A12-INPUTS!$B$12),0)) -> 0 | E12: =IF(A12="","",INPUTS!$B$24) -> 0 | F12: =IF(A12="","",IF(G11+H11=0,0,MAX(0,C12-D12-E12))) -> 78678.983 | G12: =IF(A12="","",MAX(0,G11-F12)*(1+INPUTS!$B$28)) -> 1552104 | H12: =IF(A12="","",MAX(0,H11-MAX(0,F12-G11))*(1+INPUTS!$B$28)) -> 410851.6
A13: =IF(MAX(59.5,INPUTS!$B$6)+8>INPUTS!$B$8,"",INPUTS!$B$12+(MAX(59.5,INPUTS!$B$6)-INPUTS!$B$5)+8) -> 2041.5 | B13: =IF(A13="","",MAX(59.5,INPUTS!$B$6)+8) -> 67.5 | C13: =IF(A13="","",INPUTS!$B$22*(1+INPUTS!$B$23)^(A13-INPUTS!$B$12)) -> 80645.958 | D13: =IF(A13="","",IF(B13>=INPUTS!$B$7,INPUTS!$B$25*(1+INPUTS!$B$23)^(A13-INPUTS!$B$12),0)) -> 35190.963 | E13: =IF(A13="","",INPUTS!$B$24) -> 0 | F13: =IF(A13="","",IF(G12+H12=0,0,MAX(0,C13-D13-E13))) -> 45454.994 | G13: =IF(A13="","",MAX(0,G12-F13)*(1+INPUTS!$B$28)) -> 1604581.2 | H13: =IF(A13="","",MAX(0,H12-MAX(0,F13-G12))*(1+INPUTS!$B$28)) -> 437556.95
A14: =IF(MAX(59.5,INPUTS!$B$6)+9>INPUTS!$B$8,"",INPUTS!$B$12+(MAX(59.5,INPUTS!$B$6)-INPUTS!$B$5)+9) -> 2042.5 | B14: =IF(A14="","",MAX(59.5,INPUTS!$B$6)+9) -> 68.5 | C14: =IF(A14="","",INPUTS!$B$22*(1+INPUTS!$B$23)^(A14-INPUTS!$B$12)) -> 82662.107 | D14: =IF(A14="","",IF(B14>=INPUTS!$B$7,INPUTS!$B$25*(1+INPUTS!$B$23)^(A14-INPUTS!$B$12),0)) -> 36070.737 | E14: =IF(A14="","",INPUTS!$B$24) -> 0 | F14: =IF(A14="","",IF(G13+H13=0,0,MAX(0,C14-D14-E14))) -> 46591.369 | G14: =IF(A14="","",MAX(0,G13-F14)*(1+INPUTS!$B$28)) -> 1659259.2 | H14: =IF(A14="","",MAX(0,H13-MAX(0,F14-G13))*(1+INPUTS!$B$28)) -> 465998.16
A15: =IF(MAX(59.5,INPUTS!$B$6)+10>INPUTS!$B$8,"",INPUTS!$B$12+(MAX(59.5,INPUTS!$B$6)-INPUTS!$B$5)+10) -> 2043.5 | B15: =IF(A15="","",MAX(59.5,INPUTS!$B$6)+10) -> 69.5 | C15: =IF(A15="","",INPUTS!$B$22*(1+INPUTS!$B$23)^(A15-INPUTS!$B$12)) -> 84728.659 | D15: =IF(A15="","",IF(B15>=INPUTS!$B$7,INPUTS!$B$25*(1+INPUTS!$B$23)^(A15-INPUTS!$B$12),0)) -> 36972.506 | E15: =IF(A15="","",INPUTS!$B$24) -> 0 | F15: =IF(A15="","",IF(G14+H14=0,0,MAX(0,C15-D15-E15))) -> 47756.153 | G15: =IF(A15="","",MAX(0,G14-F15)*(1+INPUTS!$B$28)) -> 1716250.7 | H15: =IF(A15="","",MAX(0,H14-MAX(0,F15-G14))*(1+INPUTS!$B$28)) -> 496288.04
A16: =IF(MAX(59.5,INPUTS!$B$6)+11>INPUTS!$B$8,"",INPUTS!$B$12+(MAX(59.5,INPUTS!$B$6)-INPUTS!$B$5)+11) -> 2044.5 | B16: =IF(A16="","",MAX(59.5,INPUTS!$B$6)+11) -> 70.5 | C16: =IF(A16="","",INPUTS!$B$22*(1+INPUTS!$B$23)^(A16-INPUTS!$B$12)) -> 86846.876 | D16: =IF(A16="","",IF(B16>=INPUTS!$B$7,INPUTS!$B$25*(1+INPUTS!$B$23)^(A16-INPUTS!$B$12),0)) -> 37896.818 | E16: =IF(A16="","",INPUTS!$B$24) -> 0 | F16: =IF(A16="","",IF(G15+H15=0,0,MAX(0,C16-D16-E16))) -> 48950.057 | G16: =IF(A16="","",MAX(0,G15-F16)*(1+INPUTS!$B$28)) -> 1775675.2 | H16: =IF(A16="","",MAX(0,H15-MAX(0,F16-G15))*(1+INPUTS!$B$28)) -> 528546.76
A17: =IF(MAX(59.5,INPUTS!$B$6)+12>INPUTS!$B$8,"",INPUTS!$B$12+(MAX(59.5,INPUTS!$B$6)-INPUTS!$B$5)+12) -> 2045.5 | B17: =IF(A17="","",MAX(59.5,INPUTS!$B$6)+12) -> 71.5 | C17: =IF(A17="","",INPUTS!$B$22*(1+INPUTS!$B$23)^(A17-INPUTS!$B$12)) -> 89018.048 | D17: =IF(A17="","",IF(B17>=INPUTS!$B$7,INPUTS!$B$25*(1+INPUTS!$B$23)^(A17-INPUTS!$B$12),0)) -> 38844.239 | E17: =IF(A17="","",INPUTS!$B$24) -> 0 | F17: =IF(A17="","",IF(G16+H16=0,0,MAX(0,C17-D17-E17))) -> 50173.809 | G17: =IF(A17="","",MAX(0,G16-F17)*(1+INPUTS!$B$28)) -> 1837659 | H17: =IF(A17="","",MAX(0,H16-MAX(0,F17-G16))*(1+INPUTS!$B$28)) -> 562902.3
A18: =IF(MAX(59.5,INPUTS!$B$6)+13>INPUTS!$B$8,"",INPUTS!$B$12+(MAX(59.5,INPUTS!$B$6)-INPUTS!$B$5)+13) -> 2046.5 | B18: =IF(A18="","",MAX(59.5,INPUTS!$B$6)+13) -> 72.5 | C18: =IF(A18="","",INPUTS!$B$22*(1+INPUTS!$B$23)^(A18-INPUTS!$B$12)) -> 91243.499 | D18: =IF(A18="","",IF(B18>=INPUTS!$B$7,INPUTS!$B$25*(1+INPUTS!$B$23)^(A18-INPUTS!$B$12),0)) -> 39815.345 | E18: =IF(A18="","",INPUTS!$B$24) -> 0 | F18: =IF(A18="","",IF(G17+H17=0,0,MAX(0,C18-D18-E18))) -> 51428.154 | G18: =IF(A18="","",MAX(0,G17-F18)*(1+INPUTS!$B$28)) -> 1902335.8 | H18: =IF(A18="","",MAX(0,H17-MAX(0,F18-G17))*(1+INPUTS!$B$28)) -> 599490.95
A19: =IF(MAX(59.5,INPUTS!$B$6)+14>INPUTS!$B$8,"",INPUTS!$B$12+(MAX(59.5,INPUTS!$B$6)-INPUTS!$B$5)+14) -> 2047.5 | B19: =IF(A19="","",MAX(59.5,INPUTS!$B$6)+14) -> 73.5 | C19: =IF(A19="","",INPUTS!$B$22*(1+INPUTS!$B$23)^(A19-INPUTS!$B$12)) -> 93524.586 | D19: =IF(A19="","",IF(B19>=INPUTS!$B$7,INPUTS!$B$25*(1+INPUTS!$B$23)^(A19-INPUTS!$B$12),0)) -> 40810.729 | E19: =IF(A19="","",INPUTS!$B$24) -> 0 | F19: =IF(A19="","",IF(G18+H18=0,0,MAX(0,C19-D19-E19))) -> 52713.858 | G19: =IF(A19="","",MAX(0,G18-F19)*(1+INPUTS!$B$28)) -> 1969847.4 | H19: =IF(A19="","",MAX(0,H18-MAX(0,F19-G18))*(1+INPUTS!$B$28)) -> 638457.86
A20: =IF(MAX(59.5,INPUTS!$B$6)+15>INPUTS!$B$8,"",INPUTS!$B$12+(MAX(59.5,INPUTS!$B$6)-INPUTS!$B$5)+15) -> 2048.5 | B20: =IF(A20="","",MAX(59.5,INPUTS!$B$6)+15) -> 74.5 | C20: =IF(A20="","",INPUTS!$B$22*(1+INPUTS!$B$23)^(A20-INPUTS!$B$12)) -> 95862.701 | D20: =IF(A20="","",IF(B20>=INPUTS!$B$7,INPUTS!$B$25*(1+INPUTS!$B$23)^(A20-INPUTS!$B$12),0)) -> 41830.997 | E20: =IF(A20="","",INPUTS!$B$24) -> 0 | F20: =IF(A20="","",IF(G19+H19=0,0,MAX(0,C20-D20-E20))) -> 54031.704 | G20: =IF(A20="","",MAX(0,G19-F20)*(1+INPUTS!$B$28)) -> 2040343.7 | H20: =IF(A20="","",MAX(0,H19-MAX(0,F20-G19))*(1+INPUTS!$B$28)) -> 679957.62
A21: =IF(MAX(59.5,INPUTS!$B$6)+16>INPUTS!$B$8,"",INPUTS!$B$12+(MAX(59.5,INPUTS!$B$6)-INPUTS!$B$5)+16) -> 2049.5 | B21: =IF(A21="","",MAX(59.5,INPUTS!$B$6)+16) -> 75.5 | C21: =IF(A21="","",INPUTS!$B$22*(1+INPUTS!$B$23)^(A21-INPUTS!$B$12)) -> 98259.268 | D21: =IF(A21="","",IF(B21>=INPUTS!$B$7,INPUTS!$B$25*(1+INPUTS!$B$23)^(A21-INPUTS!$B$12),0)) -> 42876.772 | E21: =IF(A21="","",INPUTS!$B$24) -> 0 | F21: =IF(A21="","",IF(G20+H20=0,0,MAX(0,C21-D21-E21))) -> 55382.497 | G21: =IF(A21="","",MAX(0,G20-F21)*(1+INPUTS!$B$28)) -> 2113983.7 | H21: =IF(A21="","",MAX(0,H20-MAX(0,F21-G20))*(1+INPUTS!$B$28)) -> 724154.87
A22: =IF(MAX(59.5,INPUTS!$B$6)+17>INPUTS!$B$8,"",INPUTS!$B$12+(MAX(59.5,INPUTS!$B$6)-INPUTS!$B$5)+17) -> 2050.5 | B22: =IF(A22="","",MAX(59.5,INPUTS!$B$6)+17) -> 76.5 | C22: =IF(A22="","",INPUTS!$B$22*(1+INPUTS!$B$23)^(A22-INPUTS!$B$12)) -> 100715.75 | D22: =IF(A22="","",IF(B22>=INPUTS!$B$7,INPUTS!$B$25*(1+INPUTS!$B$23)^(A22-INPUTS!$B$12),0)) -> 43948.691 | E22: =IF(A22="","",INPUTS!$B$24) -> 0 | F22: =IF(A22="","",IF(G21+H21=0,0,MAX(0,C22-D22-E22))) -> 56767.059 | G22: =IF(A22="","",MAX(0,G21-F22)*(1+INPUTS!$B$28)) -> 2190935.7 | H22: =IF(A22="","",MAX(0,H21-MAX(0,F22-G21))*(1+INPUTS!$B$28)) -> 771224.93
A23: =IF(MAX(59.5,INPUTS!$B$6)+18>INPUTS!$B$8,"",INPUTS!$B$12+(MAX(59.5,INPUTS!$B$6)-INPUTS!$B$5)+18) -> 2051.5 | B23: =IF(A23="","",MAX(59.5,INPUTS!$B$6)+18) -> 77.5 | C23: =IF(A23="","",INPUTS!$B$22*(1+INPUTS!$B$23)^(A23-INPUTS!$B$12)) -> 103233.64 | D23: =IF(A23="","",IF(B23>=INPUTS!$B$7,INPUTS!$B$25*(1+INPUTS!$B$23)^(A23-INPUTS!$B$12),0)) -> 45047.408 | E23: =IF(A23="","",INPUTS!$B$24) -> 0 | F23: =IF(A23="","",IF(G22+H22=0,0,MAX(0,C23-D23-E23))) -> 58186.236 | G23: =IF(A23="","",MAX(0,G22-F23)*(1+INPUTS!$B$28)) -> 2271378.2 | H23: =IF(A23="","",MAX(0,H22-MAX(0,F23-G22))*(1+INPUTS!$B$28)) -> 821354.55
A24: =IF(MAX(59.5,INPUTS!$B$6)+19>INPUTS!$B$8,"",INPUTS!$B$12+(MAX(59.5,INPUTS!$B$6)-INPUTS!$B$5)+19) -> 2052.5 | B24: =IF(A24="","",MAX(59.5,INPUTS!$B$6)+19) -> 78.5 | C24: =IF(A24="","",INPUTS!$B$22*(1+INPUTS!$B$23)^(A24-INPUTS!$B$12)) -> 105814.48 | D24: =IF(A24="","",IF(B24>=INPUTS!$B$7,INPUTS!$B$25*(1+INPUTS!$B$23)^(A24-INPUTS!$B$12),0)) -> 46173.593 | E24: =IF(A24="","",INPUTS!$B$24) -> 0 | F24: =IF(A24="","",IF(G23+H23=0,0,MAX(0,C24-D24-E24))) -> 59640.892 | G24: =IF(A24="","",MAX(0,G23-F24)*(1+INPUTS!$B$28)) -> 2355500.2 | H24: =IF(A24="","",MAX(0,H23-MAX(0,F24-G23))*(1+INPUTS!$B$28)) -> 874742.6
