Workbook

Sheet DASHBOARD
A1: 🌉 EARLY RETIREMENT BRIDGE PLANNER — DASHBOARD
A2: v2.1 · bridgetoretired.com · All figures pull live from INPUTS
A3: Edit INPUTS sheet to update everything → All charts and KPIs update automatically
B4: ▸ KEY METRICS
B5: TOTAL PORTFOLIO | E5: BRIDGE YEARS | H5: ANNUAL SPENDING | K5: RETIRE YEAR
B6: =INPUTS!B11+INPUTS!B12+INPUTS!B13 -> 860000 | E6: =INPUTS!B24-INPUTS!B5 -> 7.5 | H6: =INPUTS!B17 -> 40000 | K6: =INPUTS!E4 -> 2030
B8: at retirement | E8: until 59½ | H8: inflation-adjusted | K8: target year
B10: ▸ RISK FLAGS — Automatic Portfolio Health Check
B11: Bridge fully funded by taxable? | E11: =IF(INPUTS!B11>=(INPUTS!B17*(INPUTS!B24-INPUTS!B5)),"✅ FUNDED — Taxable covers all bridge years","⚠️ GAP — Review Roth contributions or Rule 72(t)") -> ⚠️ GAP — Review Roth contributions or Rule 72(t)
B12: Portfolio survives to life expectancy? | E12: =IFERROR(IF(PROJECTION!C41>0,"✅ SOLVENT — Portfolio intact at life expectancy","❌ DEPLETED — Reduce spending or increase savings"),"✅ SOLVENT") -> ✅ SOLVENT — Portfolio intact at life expectancy
B13: Withdrawal rate ≤ 4%? | E13: =IF((INPUTS!B11+INPUTS!B12+INPUTS!B13)>0,IF(INPUTS!B17/(INPUTS!B11+INPUTS!B12+INPUTS!B13)<=0.04,"✅ SAFE — "&TEXT(INPUTS!B17/(INPUTS!B11+INPUTS!B12+INPUTS!B13),"0.0%")&" withdrawal rate","⚠️ HIGH — "&TEXT(INPUTS!B17/(INPUTS!B11+INPUTS!B12+INPUTS!B13),"0.0%")&" exceeds 4% guideline"),"-") -> ⚠️ HIGH — 4.7% exceeds 4% guideline
B14: Roth ladder opportunity? | E14: =IF(INPUTS!B11>(INPUTS!B17*5),"✅ LOW URGENCY — Strong taxable buffer","⚠️ REVIEW — Roth conversions recommended in low-income bridge years") -> ⚠️ REVIEW — Roth conversions recommended in low-income bridge years
B15: Ages valid? | E15: =IF(AND(INPUTS!B5>INPUTS!B4,INPUTS!B6>INPUTS!B5),"✅ VALID — All ages correctly sequenced","❌ ERROR — Check that retire age > current age > life expectancy") -> ✅ VALID — All ages correctly sequenced
B16: Sequence of returns risk? | E16: =IF(INPUTS!B11>=(INPUTS!B17*2),"✅ BUFFERED — 2+ years cash equivalent in taxable","⚠️ RISK — Consider holding 1-2 years spending in cash/bonds") -> ✅ BUFFERED — 2+ years cash equivalent in taxable
B17: ▸ YEAR-BY-YEAR PROJECTION (Live — updates automatically with INPUTS)
B18: Year | C18: Age | D18: Taxable End | E18: 401k End | F18: Roth End | G18: Total | H18: Withdrawal | I18: Phase
B19: ='BRIDGE CLEAN'!A4 -> 2030 | C19: ='BRIDGE CLEAN'!B4 -> 52 | D19: ='BRIDGE CLEAN'!G4 -> 84000 | E19: ='BRIDGE CLEAN'!H4 -> 682500 | F19: ='BRIDGE CLEAN'!I4 -> 94500 | G19: ='BRIDGE CLEAN'!J4 -> 861000 | H19: ='BRIDGE CLEAN'!F4 -> 40000 | I19: 'Bridge (Taxable)
B20: ='BRIDGE CLEAN'!A5 -> 2031 | C20: ='BRIDGE CLEAN'!B5 -> 53 | D20: ='BRIDGE CLEAN'!G5 -> 45150 | E20: ='BRIDGE CLEAN'!H5 -> 716625 | F20: ='BRIDGE CLEAN'!I5 -> 99225 | G20: ='BRIDGE CLEAN'!J5 -> 861000 | H20: ='BRIDGE CLEAN'!F5 -> 41000 | I20: 'Bridge (Taxable)
B21: ='BRIDGE CLEAN'!A6 -> 2032 | C21: ='BRIDGE CLEAN'!B6 -> 54 | D21: ='BRIDGE CLEAN'!G6 -> 3281.25 | E21: ='BRIDGE CLEAN'!H6 -> 752456.25 | F21: ='BRIDGE CLEAN'!I6 -> 104186.25 | G21: ='BRIDGE CLEAN'!J6 -> 859923.75 | H21: ='BRIDGE CLEAN'!F6 -> 42025 | I21: 'Bridge (Taxable)
B22: ='BRIDGE CLEAN'!A7 -> 2033 | C22: ='BRIDGE CLEAN'!B7 -> 55 | D22: ='BRIDGE CLEAN'!G7 -> 0 | E22: ='BRIDGE CLEAN'!H7 -> 790079.06 | F22: ='BRIDGE CLEAN'!I7 -> 67611.469 | G22: ='BRIDGE CLEAN'!J7 -> 857690.53 | H22: ='BRIDGE CLEAN'!F7 -> 43075.625 | I22: 'Bridge (Taxable)
B23: ='BRIDGE CLEAN'!A8 -> 2034 | C23: ='BRIDGE CLEAN'!B8 -> 56 | D23: ='BRIDGE CLEAN'!G8 -> 0 | E23: ='BRIDGE CLEAN'!H8 -> 829583.02 | F23: ='BRIDGE CLEAN'!I8 -> 24631.901 | G23: ='BRIDGE CLEAN'!J8 -> 854214.92 | H23: ='BRIDGE CLEAN'!F8 -> 44152.516 | I23: 'Bridge (Taxable)
B24: ='BRIDGE CLEAN'!A9 -> 2035 | C24: ='BRIDGE CLEAN'!B9 -> 57 | D24: ='BRIDGE CLEAN'!G9 -> 0 | E24: ='BRIDGE CLEAN'!H9 -> 849406.52 | F24: ='BRIDGE CLEAN'!I9 -> 0 | G24: ='BRIDGE CLEAN'!J9 -> 849406.52 | H24: ='BRIDGE CLEAN'!F9 -> 45256.329 | I24: 'Bridge (Taxable)
B25: ='BRIDGE CLEAN'!A10 -> 2036 | C25: ='BRIDGE CLEAN'!B10 -> 58 | D25: ='BRIDGE CLEAN'!G10 -> 0 | E25: ='BRIDGE CLEAN'!H10 -> 843169.72 | F25: ='BRIDGE CLEAN'!I10 -> 0 | G25: ='BRIDGE CLEAN'!J10 -> 843169.72 | H25: ='BRIDGE CLEAN'!F10 -> 46387.737 | I25: 'Bridge (Taxable)
B26: ='BRIDGE CLEAN'!A11 -> 2037 | C26: ='BRIDGE CLEAN'!B11 -> 59 | D26: ='BRIDGE CLEAN'!G11 -> 0 | E26: ='BRIDGE CLEAN'!H11 -> 835403.4 | F26: ='BRIDGE CLEAN'!I11 -> 0 | G26: ='BRIDGE CLEAN'!J11 -> 835403.4 | H26: ='BRIDGE CLEAN'!F11 -> 47547.43 | I26: 'Bridge (Taxable)
B27: ='POST-59.5'!A4 -> 2038 | C27: ='POST-59.5'!B4 -> 59.5 | D27: ='POST-59.5'!G4 -> 0 | E27: ='POST-59.5'!H4 -> 826000.65 | F27: ='POST-59.5'!I4 -> 0 | G27: ='POST-59.5'!J4 -> 826000.65 | H27: ='POST-59.5'!F4 -> 48736.116 | I27: =IF('POST-59.5'!B4>=INPUTS!B7,"Post-SS","Post-59½") -> Post-59½
B28: ='POST-59.5'!A5 -> 2039 | C28: ='POST-59.5'!B5 -> 60.5 | D28: ='POST-59.5'!G5 -> 0 | E28: ='POST-59.5'!H5 -> 814848.44 | F28: ='POST-59.5'!I5 -> 0 | G28: ='POST-59.5'!J5 -> 814848.44 | H28: ='POST-59.5'!F5 -> 49954.519 | I28: =IF('POST-59.5'!B5>=INPUTS!B7,"Post-SS","Post-59½") -> Post-59½
B29: ='POST-59.5'!A6 -> 2040 | C29: ='POST-59.5'!B6 -> 61.5 | D29: ='POST-59.5'!G6 -> 0 | E29: ='POST-59.5'!H6 -> 801827.31 | F29: ='POST-59.5'!I6 -> 0 | G29: ='POST-59.5'!J6 -> 801827.31 | H29: ='POST-59.5'!F6 -> 51203.382 | I29: =IF('POST-59.5'!B6>=INPUTS!B7,"Post-SS","Post-59½") -> Post-59½
B30: ='POST-59.5'!A7 -> 2041 | C30: ='POST-59.5'!B7 -> 62.5 | D30: ='POST-59.5'!G7 -> 0 | E30: ='POST-59.5'!H7 -> 786811.04 | F30: ='POST-59.5'!I7 -> 0 | G30: ='POST-59.5'!J7 -> 786811.04 | H30: ='POST-59.5'!F7 -> 52483.466 | I30: =IF('POST-59.5'!B7>=INPUTS!B7,"Post-SS","Post-59½") -> Post-59½
B31: ='POST-59.5'!A8 -> 2042 | C31: ='POST-59.5'!B8 -> 63.5 | D31: ='POST-59.5'!G8 -> 0 | E31: ='POST-59.5'!H8 -> 769666.26 | F31: ='POST-59.5'!I8 -> 0 | G31: ='POST-59.5'!J8 -> 769666.26 | H31: ='POST-59.5'!F8 -> 53795.553 | I31: =IF('POST-59.5'!B8>=INPUTS!B7,"Post-SS","Post-59½") -> Post-59½
B32: ='POST-59.5'!A9 -> 2043 | C32: ='POST-59.5'!B9 -> 64.5 | D32: ='POST-59.5'!G9 -> 0 | E32: ='POST-59.5'!H9 -> 750252.11 | F32: ='POST-59.5'!I9 -> 0 | G32: ='POST-59.5'!J9 -> 750252.11 | H32: ='POST-59.5'!F9 -> 55140.442 | I32: =IF('POST-59.5'!B9>=INPUTS!B7,"Post-SS","Post-59½") -> Post-59½
B33: ='POST-59.5'!A10 -> 2044 | C33: ='POST-59.5'!B10 -> 65.5 | D33: ='POST-59.5'!G10 -> 0 | E33: ='POST-59.5'!H10 -> 728419.81 | F33: ='POST-59.5'!I10 -> 0 | G33: ='POST-59.5'!J10 -> 728419.81 | H33: ='POST-59.5'!F10 -> 56518.953 | I33: =IF('POST-59.5'!B10>=INPUTS!B7,"Post-SS","Post-59½") -> Post-59½
B34: ='POST-59.5'!A11 -> 2045 | C34: ='POST-59.5'!B11 -> 66.5 | D34: ='POST-59.5'!G11 -> 0 | E34: ='POST-59.5'!H11 -> 704012.28 | F34: ='POST-59.5'!I11 -> 0 | G34: ='POST-59.5'!J11 -> 704012.28 | H34: ='POST-59.5'!F11 -> 57931.927 | I34: =IF('POST-59.5'!B11>=INPUTS!B7,"Post-SS","Post-59½") -> Post-59½
B35: ='POST-59.5'!A12 -> 2046 | C35: ='POST-59.5'!B12 -> 67.5 | D35: ='POST-59.5'!G12 -> 0 | E35: ='POST-59.5'!H12 -> 718156.79 | F35: ='POST-59.5'!I12 -> 0 | G35: ='POST-59.5'!J12 -> 718156.79 | H35: ='POST-59.5'!F12 -> 20053.43 | I35: =IF('POST-59.5'!B12>=INPUTS!B7,"Post-SS","Post-59½") -> Post-SS
B36: ='POST-59.5'!A13 -> 2047 | C36: ='POST-59.5'!B13 -> 68.5 | D36: ='POST-59.5'!G13 -> 0 | E36: ='POST-59.5'!H13 -> 732482.13 | F36: ='POST-59.5'!I13 -> 0 | G36: ='POST-59.5'!J13 -> 732482.13 | H36: ='POST-59.5'!F13 -> 20554.766 | I36: =IF('POST-59.5'!B13>=INPUTS!B7,"Post-SS","Post-59½") -> Post-SS
B37: ='POST-59.5'!A14 -> 2048 | C37: ='POST-59.5'!B14 -> 69.5 | D37: ='POST-59.5'!G14 -> 0 | E37: ='POST-59.5'!H14 -> 746984.17 | F37: ='POST-59.5'!I14 -> 0 | G37: ='POST-59.5'!J14 -> 746984.17 | H37: ='POST-59.5'!F14 -> 21068.635 | I37: =IF('POST-59.5'!B14>=INPUTS!B7,"Post-SS","Post-59½") -> Post-SS
B38: ='POST-59.5'!A15 -> 2049 | C38: ='POST-59.5'!B15 -> 70.5 | D38: ='POST-59.5'!G15 -> 0 | E38: ='POST-59.5'!H15 -> 761658.26 | F38: ='POST-59.5'!I15 -> 0 | G38: ='POST-59.5'!J15 -> 761658.26 | H38: ='POST-59.5'!F15 -> 21595.351 | I38: =IF('POST-59.5'!B15>=INPUTS!B7,"Post-SS","Post-59½") -> Post-SS
B39: ='POST-59.5'!A16 -> 2050 | C39: ='POST-59.5'!B16 -> 71.5 | D39: ='POST-59.5'!G16 -> 0 | E39: ='POST-59.5'!H16 -> 776499.17 | F39: ='POST-59.5'!I16 -> 0 | G39: ='POST-59.5'!J16 -> 776499.17 | H39: ='POST-59.5'!F16 -> 22135.235 | I39: =IF('POST-59.5'!B16>=INPUTS!B7,"Post-SS","Post-59½") -> Post-SS
B40: ='POST-59.5'!A17 -> 2051 | C40: ='POST-59.5'!B17 -> 72.5 | D40: ='POST-59.5'!G17 -> 0 | E40: ='POST-59.5'!H17 -> 791501.09 | F40: ='POST-59.5'!I17 -> 0 | G40: ='POST-59.5'!J17 -> 791501.09 | H40: ='POST-59.5'!F17 -> 22688.616 | I40: =IF('POST-59.5'!B17>=INPUTS!B7,"Post-SS","Post-59½") -> Post-SS
B41: ='POST-59.5'!A18 -> 2052 | C41: ='POST-59.5'!B18 -> 73.5 | D41: ='POST-59.5'!G18 -> 0 | E41: ='POST-59.5'!H18 -> 806657.52 | F41: ='POST-59.5'!I18 -> 0 | G41: ='POST-59.5'!J18 -> 806657.52 | H41: ='POST-59.5'!F18 -> 23255.831 | I41: =IF('POST-59.5'!B18>=INPUTS!B7,"Post-SS","Post-59½") -> Post-SS
B42: ='POST-59.5'!A19 -> 2053 | C42: ='POST-59.5'!B19 -> 74.5 | D42: ='POST-59.5'!G19 -> 0 | E42: ='POST-59.5'!H19 -> 821961.3 | F42: ='POST-59.5'!I19 -> 0 | G42: ='POST-59.5'!J19 -> 821961.3 | H42: ='POST-59.5'!F19 -> 23837.227 | I42: =IF('POST-59.5'!B19>=INPUTS!B7,"Post-SS","Post-59½") -> Post-SS
...

Sheet START HERE
A1: 🌉 EARLY RETIREMENT BRIDGE PLANNER
A2: v2.1 · Last updated: Feb 2026 · bridgetoretired.com
A3: Sheet | B3: What it does
A4: 🗺️ DASHBOARD | B4: START HERE → KPI cards, charts, risk flags. Mission control.
A5: 📋 INPUTS | B5: Enter your ages, balances & assumptions. Everything else pulls from here.
A6: 🌉 BRIDGE CLEAN | B6: Bridge years plan (age < 59½). Taxable first, 401k grows untouched.
A7: 📈 POST-59.5 | B7: Post-59½ plan. 401k draws first. Roth preserved as long as possible.
A8: 🗺️ PROJECTION | B8: Full lifetime summary from retirement to life expectancy.
A9: ⚠️ RISK FLAGS | B9: Auto-checks: solvency, withdrawal rate, bridge coverage, sequence risk.
A11: ⚡ PRO v3 COMING SOON — Monte Carlo · Tax Optimizer · PDF Reports
A12: Visit bridgetoretired.com to get notified

Sheet INPUTS
A1: EARLY RETIREMENT BRIDGE PLANNER
A3: TIMELINE
A4: Current Age | B4: 48 | D4: Retire Year | E4: =B8+(B5-B4) -> 2030
A5: Retirement Age | B5: 52 | D5: End Year | E5: =B8+(B6-B4) -> 2068
A6: Life Expectancy | B6: 90 | D6: Bridge End Age | E6: =B24 -> 59.5
A7: Social Security Claim Age | B7: 67
A8: First Projection Year | B8: 2026
A9: SS Annual Benefit ($/yr, today $) | B9: 24000
A10: ACCOUNT BALANCES
A11: Taxable Brokerage ($) | B11: 120000
A12: Traditional 401(k) ($) | B12: 650000
A13: Roth IRA ($) | B13: 90000
A14: Total Portfolio | B14: =B11+B12+B13 -> 860000
A16: SPENDING & ASSUMPTIONS
A17: Annual Spending Need ($/yr) | B17: 40000
A18: Expected Annual Return (%) | B18: 0.05
A19: Inflation (%) | B19: 0.025
A20: Inflation-Adjust Spending? | B20: Yes
A21: Withdrawal Order | B21: Taxable → 401k → Roth
A23: RULES
A24: 401(k) Penalty-Free Access Age | B24: 59.5
A25: Roth contributions (not earnings) can be withdrawn penalty-free at any age.
A26: Roth Use Toggle | B26: No (dropdown later)

Sheet BRIDGE YEARS
A1: Year | B1: Age | C1: Starting Balance | D1: Withdrawal | E1: Account Used | F1: Ending Balance
A2: =INPUTS!E4 -> 2030 | B2: {=IF(A2:A1000="",,INPUTS!B4+(A2:A1000-INPUTS!B8))} -> 52 | C2: =INPUTS!B11+INPUTS!B12+INPUTS!B13 -> 860000 | D2: {=IF(A2:A1000="",,VALUE(INPUTS!B17))} -> 40000 | E2: {=IF(A2:A1000="",,"Taxable")} -> Taxable | F2: =(C2-D2)*(1+INPUTS!B18) -> 861000
A3: =A2+1 -> 2031 | B3: 53 | C3: =F2 -> 861000 | D3: 40000 | E3: Taxable | F3: =IFERROR((C3-D3)*(1+INPUTS!B18),"") -> 862050
A4: =A3+1 -> 2032 | B4: 54 | C4: =F3 -> 862050 | D4: 40000 | E4: Taxable | F4: =IFERROR((C4-D4)*(1+INPUTS!B19),"") -> 842601.25
A5: =A4+1 -> 2033 | B5: 55 | C5: =F4 -> 842601.25 | D5: 40000 | E5: Taxable | F5: =IFERROR((C5-D5)*(1+INPUTS!B20),"")
A6: =A5+1 -> 2034 | B6: 56 | C6: =F5 | D6: 40000 | E6: Taxable | F6: =IFERROR((C6-D6)*(1+INPUTS!B21),"")
A7: =A6+1 -> 2035 | B7: 57 | C7: =F6 | D7: 40000 | E7: Taxable | F7: =IFERROR((C7-D7)*(1+INPUTS!B22),"")
A8: =A7+1 -> 2036 | B8: 58 | C8: =F7 | D8: 40000 | E8: Taxable | F8: =IFERROR((C8-D8)*(1+INPUTS!B23),"")
A9: =A8+1 -> 2037 | B9: 59 | C9: =F8 | D9: 40000 | E9: Taxable | F9: =IFERROR((C9-D9)*(1+INPUTS!B24),"")
B10: 0 | D10: 0 | E10: 0
B11: 0 | D11: 0 | E11: 0
B12: 0 | D12: 0 | E12: 0
B13: 0 | D13: 0 | E13: 0
B14: 0 | D14: 0 | E14: 0
B15: 0 | D15: 0 | E15: 0
B16: 0 | D16: 0 | E16: 0
B17: 0 | D17: 0 | E17: 0
B18: 0 | D18: 0 | E18: 0
B19: 0 | D19: 0 | E19: 0
B20: 0 | D20: 0 | E20: 0
B21: 0 | D21: 0 | E21: 0
... B1000: 0 | D1000: 0 | E1000: 0

Sheet BRIDGE CLEAN
A1: BRIDGE YEARS (Age < 59½) — Taxable First
A2: 401(k) grows untouched. Roth used only if taxable is exhausted.
A3: Year | B3: Age | C3: Taxable Start | D3: 401k Start | E3: Roth Start | F3: Withdrawal | G3: Taxable End | H3: 401k End | I3: Roth End | J3: Total End
A4: =INPUTS!E4 -> 2030 | B4: =INPUTS!B5 -> 52 | C4: =INPUTS!B11 -> 120000 | D4: =INPUTS!B12 -> 650000 | E4: =INPUTS!B13 -> 90000 | F4: =INPUTS!B17 -> 40000 | G4: =MAX(0,C4-F4)*(1+INPUTS!B18) -> 84000 | H4: =MAX(0,D4-MAX(0,F4-C4-E4))*(1+INPUTS!B18) -> 682500 | I4: =MAX(0,E4-MAX(0,F4-C4))*(1+INPUTS!B18) -> 94500 | J4: =G4+H4+I4 -> 861000
A5: =INPUTS!E4+1 -> 2031 | B5: =INPUTS!B5+1 -> 53 | C5: =G4 -> 84000 | D5: =H4 -> 682500 | E5: =I4 -> 94500 | F5: =F4*(1+INPUTS!B19) -> 41000 | G5: =MAX(0,C5-F5)*(1+INPUTS!B18) -> 45150 | H5: =MAX(0,D5-MAX(0,F5-C5-E5))*(1+INPUTS!B18) -> 716625 | I5: =MAX(0,E5-MAX(0,F5-C5))*(1+INPUTS!B18) -> 99225 | J5: =G5+H5+I5 -> 861000
A6: =INPUTS!E4+2 -> 2032 | B6: =INPUTS!B5+2 -> 54 | C6: =G5 -> 45150 | D6: =H5 -> 716625 | E6: =I5 -> 99225 | F6: =F5*(1+INPUTS!B19) -> 42025 | G6: =MAX(0,C6-F6)*(1+INPUTS!B18) -> 3281.25 | H6: =MAX(0,D6-MAX(0,F6-C6-E6))*(1+INPUTS!B18) -> 752456.25 | I6: =MAX(0,E6-MAX(0,F6-C6))*(1+INPUTS!B18) -> 104186.25 | J6: =G6+H6+I6 -> 859923.75
A7: =INPUTS!E4+3 -> 2033 | B7: =INPUTS!B5+3 -> 55 | C7: =G6 -> 3281.25 | D7: =H6 -> 752456.25 | E7: =I6 -> 104186.25 | F7: =F6*(1+INPUTS!B19) -> 43075.625 | G7: =MAX(0,C7-F7)*(1+INPUTS!B18) -> 0 | H7: =MAX(0,D7-MAX(0,F7-C7-E7))*(1+INPUTS!B18) -> 790079.06 | I7: =MAX(0,E7-MAX(0,F7-C7))*(1+INPUTS!B18) -> 67611.469 | J7: =G7+H7+I7 -> 857690.53
A8: =INPUTS!E4+4 -> 2034 | B8: =INPUTS!B5+4 -> 56 | C8: =G7 -> 0 | D8: =H7 -> 790079.06 | E8: =I7 -> 67611.469 | F8: =F7*(1+INPUTS!B19) -> 44152.516 | G8: =MAX(0,C8-F8)*(1+INPUTS!B18) -> 0 | H8: =MAX(0,D8-MAX(0,F8-C8-E8))*(1+INPUTS!B18) -> 829583.02 | I8: =MAX(0,E8-MAX(0,F8-C8))*(1+INPUTS!B18) -> 24631.901 | J8: =G8+H8+I8 -> 854214.92
A9: =INPUTS!E4+5 -> 2035 | B9: =INPUTS!B5+5 -> 57 | C9: =G8 -> 0 | D9: =H8 -> 829583.02 | E9: =I8 -> 24631.901 | F9: =F8*(1+INPUTS!B19) -> 45256.329 | G9: =MAX(0,C9-F9)*(1+INPUTS!B18) -> 0 | H9: =MAX(0,D9-MAX(0,F9-C9-E9))*(1+INPUTS!B18) -> 849406.52 | I9: =MAX(0,E9-MAX(0,F9-C9))*(1+INPUTS!B18) -> 0 | J9: =G9+H9+I9 -> 849406.52
A10: =INPUTS!E4+6 -> 2036 | B10: =INPUTS!B5+6 -> 58 | C10: =G9 -> 0 | D10: =H9 -> 849406.52 | E10: =I9 -> 0 | F10: =F9*(1+INPUTS!B19) -> 46387.737 | G10: =MAX(0,C10-F10)*(1+INPUTS!B18) -> 0 | H10: =MAX(0,D10-MAX(0,F10-C10-E10))*(1+INPUTS!B18) -> 843169.72 | I10: =MAX(0,E10-MAX(0,F10-C10))*(1+INPUTS!B18) -> 0 | J10: =G10+H10+I10 -> 843169.72
A11: =INPUTS!E4+7 -> 2037 | B11: =INPUTS!B5+7 -> 59 | C11: =G10 -> 0 | D11: =H10 -> 843169.72 | E11: =I10 -> 0 | F11: =F10*(1+INPUTS!B19) -> 47547.43 | G11: =MAX(0,C11-F11)*(1+INPUTS!B18) -> 0 | H11: =MAX(0,D11-MAX(0,F11-C11-E11))*(1+INPUTS!B18) -> 835403.4 | I11: =MAX(0,E11-MAX(0,F11-C11))*(1+INPUTS!B18) -> 0 | J11: =G11+H11+I11 -> 835403.4
A12: TOTALS | F12: =SUM(F4:F11) -> 349444.64

Sheet POST-59.5
A1: POST-59½ (401k Accessible)
A2: Draw from 401(k) first. Roth used only if 401k exhausted. Taxable continues to compound.
A3: Year | B3: Age | C3: Taxable | D3: 401k Start | E3: Roth Start | F3: Withdrawal | G3: Taxable End | H3: 401k End | I3: Roth End | J3: Total End
A4: ='BRIDGE CLEAN'!A11+1 -> 2038 | B4: =INPUTS!B24 -> 59.5 | C4: ='BRIDGE CLEAN'!G11 -> 0 | D4: ='BRIDGE CLEAN'!H11 -> 835403.4 | E4: ='BRIDGE CLEAN'!I11 -> 0 | F4: =MAX(0,'BRIDGE CLEAN'!F11*(1+INPUTS!B19)^(A4-'BRIDGE CLEAN'!A11)-IF(B4>=INPUTS!B7,INPUTS!B9*(1+INPUTS!B19)^(A4-INPUTS!B8),0)) -> 48736.116 | G4: =C4*(1+INPUTS!B18) -> 0 | H4: =MAX(0,D4-F4)*(1+INPUTS!B18) -> 826000.65 | I4: =MAX(0,E4-MAX(0,F4-D4))*(1+INPUTS!B18) -> 0 | J4: =IF(B4>INPUTS!B6,"—",G4+H4+I4) -> 826000.65
A5: =A4+1 -> 2039 | B5: =B4+1 -> 60.5 | C5: =G4 -> 0 | D5: =H4 -> 826000.65 | E5: =I4 -> 0 | F5: =MAX(0,'BRIDGE CLEAN'!F11*(1+INPUTS!B19)^(A5-'BRIDGE CLEAN'!A11)-IF(B5>=INPUTS!B7,INPUTS!B9*(1+INPUTS!B19)^(A5-INPUTS!B8),0)) -> 49954.519 | G5: =C5*(1+INPUTS!B18) -> 0 | H5: =MAX(0,D5-F5)*(1+INPUTS!B18) -> 814848.44 | I5: =MAX(0,E5-MAX(0,F5-D5))*(1+INPUTS!B18) -> 0 | J5: =IF(B5>INPUTS!B6,"—",G5+H5+I5) -> 814848.44
A6: =A5+1 -> 2040 | B6: =B5+1 -> 61.5 | C6: =G5 -> 0 | D6: =H5 -> 814848.44 | E6: =I5 -> 0 | F6: =MAX(0,'BRIDGE CLEAN'!F11*(1+INPUTS!B19)^(A6-'BRIDGE CLEAN'!A11)-IF(B6>=INPUTS!B7,INPUTS!B9*(1+INPUTS!B19)^(A6-INPUTS!B8),0)) -> 51203.382 | G6: =C6*(1+INPUTS!B18) -> 0 | H6: =MAX(0,D6-F6)*(1+INPUTS!B18) -> 801827.31 | I6: =MAX(0,E6-MAX(0,F6-D6))*(1+INPUTS!B18) -> 0 | J6: =IF(B6>INPUTS!B6,"—",G6+H6+I6) -> 801827.31
A7: =A6+1 -> 2041 | B7: =B6+1 -> 62.5 | C7: =G6 -> 0 | D7: =H6 -> 801827.31 | E7: =I6 -> 0 | F7: =MAX(0,'BRIDGE CLEAN'!F11*(1+INPUTS!B19)^(A7-'BRIDGE CLEAN'!A11)-IF(B7>=INPUTS!B7,INPUTS!B9*(1+INPUTS!B19)^(A7-INPUTS!B8),0)) -> 52483.466 | G7: =C7*(1+INPUTS!B18) -> 0 | H7: =MAX(0,D7-F7)*(1+INPUTS!B18) -> 786811.04 | I7: =MAX(0,E7-MAX(0,F7-D7))*(1+INPUTS!B18) -> 0 | J7: =IF(B7>INPUTS!B6,"—",G7+H7+I7) -> 786811.04
A8: =A7+1 -> 2042 | B8: =B7+1 -> 63.5 | C8: =G7 -> 0 | D8: =H7 -> 786811.04 | E8: =I7 -> 0 | F8: =MAX(0,'BRIDGE CLEAN'!F11*(1+INPUTS!B19)^(A8-'BRIDGE CLEAN'!A11)-IF(B8>=INPUTS!B7,INPUTS!B9*(1+INPUTS!B19)^(A8-INPUTS!B8),0)) -> 53795.553 | G8: =C8*(1+INPUTS!B18) -> 0 | H8: =MAX(0,D8-F8)*(1+INPUTS!B18) -> 769666.26 | I8: =MAX(0,E8-MAX(0,F8-D8))*(1+INPUTS!B18) -> 0 | J8: =IF(B8>INPUTS!B6,"—",G8+H8+I8) -> 769666.26
A9: =A8+1 -> 2043 | B9: =B8+1 -> 64.5 | C9: =G8 -> 0 | D9: =H8 -> 769666.26 | E9: =I8 -> 0 | F9: =MAX(0,'BRIDGE CLEAN'!F11*(1+INPUTS!B19)^(A9-'BRIDGE CLEAN'!A11)-IF(B9>=INPUTS!B7,INPUTS!B9*(1+INPUTS!B19)^(A9-INPUTS!B8),0)) -> 55140.442 | G9: =C9*(1+INPUTS!B18) -> 0 | H9: =MAX(0,D9-F9)*(1+INPUTS!B18) -> 750252.11 | I9: =MAX(0,E9-MAX(0,F9-D9))*(1+INPUTS!B18) -> 0 | J9: =IF(B9>INPUTS!B6,"—",G9+H9+I9) -> 750252.11
A10: =A9+1 -> 2044 | B10: =B9+1 -> 65.5 | C10: =G9 -> 0 | D10: =H9 -> 750252.11 | E10: =I9 -> 0 | F10: =MAX(0,'BRIDGE CLEAN'!F11*(1+INPUTS!B19)^(A10-'BRIDGE CLEAN'!A11)-IF(B10>=INPUTS!B7,INPUTS!B9*(1+INPUTS!B19)^(A10-INPUTS!B8),0)) -> 56518.953 | G10: =C10*(1+INPUTS!B18) -> 0 | H10: =MAX(0,D10-F10)*(1+INPUTS!B18) -> 728419.81 | I10: =MAX(0,E10-MAX(0,F10-D10))*(1+INPUTS!B18) -> 0 | J10: =IF(B10>INPUTS!B6,"—",G10+H10+I10) -> 728419.81
A11: =A10+1 -> 2045 | B11: =B10+1 -> 66.5 | C11: =G10 -> 0 | D11: =H10 -> 728419.81 | E11: =I10 -> 0 | F11: =MAX(0,'BRIDGE CLEAN'!F11*(1+INPUTS!B19)^(A11-'BRIDGE CLEAN'!A11)-IF(B11>=INPUTS!B7,INPUTS!B9*(1+INPUTS!B19)^(A11-INPUTS!B8),0)) -> 57931.927 | G11: =C11*(1+INPUTS!B18) -> 0 | H11: =MAX(0,D11-F11)*(1+INPUTS!B18) -> 704012.28 | I11: =MAX(0,E11-MAX(0,F11-D11))*(1+INPUTS!B18) -> 0 | J11: =IF(B11>INPUTS!B6,"—",G11+H11+I11) -> 704012.28
A12: =A11+1 -> 2046 | B12: =B11+1 -> 67.5 | C12: =G11 -> 0 | D12: =H11 -> 704012.28 | E12: =I11 -> 0 | F12: =MAX(0,'BRIDGE CLEAN'!F11*(1+INPUTS!B19)^(A12-'BRIDGE CLEAN'!A11)-IF(B12>=INPUTS!B7,INPUTS!B9*(1+INPUTS!B19)^(A12-INPUTS!B8),0)) -> 20053.43 | G12: =C12*(1+INPUTS!B18) -> 0 | H12: =MAX(0,D12-F12)*(1+INPUTS!B18) -> 718156.79 | I12: =MAX(0,E12-MAX(0,F12-D12))*(1+INPUTS!B18) -> 0 | J12: =IF(B12>INPUTS!B6,"—",G12+H12+I12) -> 718156.79
A13: =A12+1 -> 2047 | B13: =B12+1 -> 68.5 | C13: =G12 -> 0 | D13: =H12 -> 718156.79 | E13: =I12 -> 0 | F13: =MAX(0,'BRIDGE CLEAN'!F11*(1+INPUTS!B19)^(A13-'BRIDGE CLEAN'!A11)-IF(B13>=INPUTS!B7,INPUTS!B9*(1+INPUTS!B19)^(A13-INPUTS!B8),0)) -> 20554.766 | G13: =C13*(1+INPUTS!B18) -> 0 | H13: =MAX(0,D13-F13)*(1+INPUTS!B18) -> 732482.13 | I13: =MAX(0,E13-MAX(0,F13-D13))*(1+INPUTS!B18) -> 0 | J13: =IF(B13>INPUTS!B6,"—",G13+H13+I13) -> 732482.13
A14: =A13+1 -> 2048 | B14: =B13+1 -> 69.5 | C14: =G13 -> 0 | D14: =H13 -> 732482.13 | E14: =I13 -> 0 | F14: =MAX(0,'BRIDGE CLEAN'!F11*(1+INPUTS!B19)^(A14-'BRIDGE CLEAN'!A11)-IF(B14>=INPUTS!B7,INPUTS!B9*(1+INPUTS!B19)^(A14-INPUTS!B8),0)) -> 21068.635 | G14: =C14*(1+INPUTS!B18) -> 0 | H14: =MAX(0,D14-F14)*(1+INPUTS!B18) -> 746984.17 | I14: =MAX(0,E14-MAX(0,F14-D14))*(1+INPUTS!B18) -> 0 | J14: =IF(B14>INPUTS!B6,"—",G14+H14+I14) -> 746984.17
A15: =A14+1 -> 2049 | B15: =B14+1 -> 70.5 | C15: =G14 -> 0 | D15: =H14 -> 746984.17 | E15: =I14 -> 0 | F15: =MAX(0,'BRIDGE CLEAN'!F11*(1+INPUTS!B19)^(A15-'BRIDGE CLEAN'!A11)-IF(B15>=INPUTS!B7,INPUTS!B9*(1+INPUTS!B19)^(A15-INPUTS!B8),0)) -> 21595.351 | G15: =C15*(1+INPUTS!B18) -> 0 | H15: =MAX(0,D15-F15)*(1+INPUTS!B18) -> 761658.26 | I15: =MAX(0,E15-MAX(0,F15-D15))*(1+INPUTS!B18) -> 0 | J15: =IF(B15>INPUTS!B6,"—",G15+H15+I15) -> 761658.26
A16: =A15+1 -> 2050 | B16: =B15+1 -> 71.5 | C16: =G15 -> 0 | D16: =H15 -> 761658.26 | E16: =I15 -> 0 | F16: =MAX(0,'BRIDGE CLEAN'!F11*(1+INPUTS!B19)^(A16-'BRIDGE CLEAN'!A11)-IF(B16>=INPUTS!B7,INPUTS!B9*(1+INPUTS!B19)^(A16-INPUTS!B8),0)) -> 22135.235 | G16: =C16*(1+INPUTS!B18) -> 0 | H16: =MAX(0,D16-F16)*(1+INPUTS!B18) -> 776499.17 | I16: =MAX(0,E16-MAX(0,F16-D16))*(1+INPUTS!B18) -> 0 | J16: =IF(B16>INPUTS!B6,"—",G16+H16+I16) -> 776499.17
A17: =A16+1 -> 2051 | B17: =B16+1 -> 72.5 | C17: =G16 -> 0 | D17: =H16 -> 776499.17 | E17: =I16 -> 0 | F17: =MAX(0,'BRIDGE CLEAN'!F11*(1+INPUTS!B19)^(A17-'BRIDGE CLEAN'!A11)-IF(B17>=INPUTS!B7,INPUTS!B9*(1+INPUTS!B19)^(A17-INPUTS!B8),0)) -> 22688.616 | G17: =C17*(1+INPUTS!B18) -> 0 | H17: =MAX(0,D17-F17)*(1+INPUTS!B18) -> 791501.09 | I17: =MAX(0,E17-MAX(0,F17-D17))*(1+INPUTS!B18) -> 0 | J17: =IF(B17>INPUTS!B6,"—",G17+H17+I17) -> 791501.09
A18: =A17+1 -> 2052 | B18: =B17+1 -> 73.5 | C18: =G17 -> 0 | D18: =H17 -> 791501.09 | E18: =I17 -> 0 | F18: =MAX(0,'BRIDGE CLEAN'!F11*(1+INPUTS!B19)^(A18-'BRIDGE CLEAN'!A11)-IF(B18>=INPUTS!B7,INPUTS!B9*(1+INPUTS!B19)^(A18-INPUTS!B8),0)) -> 23255.831 | G18: =C18*(1+INPUTS!B18) -> 0 | H18: =MAX(0,D18-F18)*(1+INPUTS!B18) -> 806657.52 | I18: =MAX(0,E18-MAX(0,F18-D18))*(1+INPUTS!B18) -> 0 | J18: =IF(B18>INPUTS!B6,"—",G18+H18+I18) -> 806657.52
A19: =A18+1 -> 2053 | B19: =B18+1 -> 74.5 | C19: =G18 -> 0 | D19: =H18 -> 806657.52 | E19: =I18 -> 0 | F19: =MAX(0,'BRIDGE CLEAN'!F11*(1+INPUTS!B19)^(A19-'BRIDGE CLEAN'!A11)-IF(B19>=INPUTS!B7,INPUTS!B9*(1+INPUTS!B19)^(A19-INPUTS!B8),0)) -> 23837.227 | G19: =C19*(1+INPUTS!B18) -> 0 | H19: =MAX(0,D19-F19)*(1+INPUTS!B18) -> 821961.3 | I19: =MAX(0,E19-MAX(0,F19-D19))*(1+INPUTS!B18) -> 0 | J19: =IF(B19>INPUTS!B6,"—",G19+H19+I19) -> 821961.3
A20: =A19+1 -> 2054 | B20: =B19+1 -> 75.5 | C20: =G19 -> 0 | D20: =H19 -> 821961.3 | E20: =I19 -> 0 | F20: =MAX(0,'BRIDGE CLEAN'!F11*(1+INPUTS!B19)^(A20-'BRIDGE CLEAN'!A11)-IF(B20>=INPUTS!B7,INPUTS!B9*(1+INPUTS!B19)^(A20-INPUTS!B8),0)) -> 24433.158 | G20: =C20*(1+INPUTS!B18) -> 0 | H20: =MAX(0,D20-F20)*(1+INPUTS!B18) -> 837404.55 | I20: =MAX(0,E20-MAX(0,F20-D20))*(1+INPUTS!B18) -> 0 | J20: =IF(B20>INPUTS!B6,"—",G20+H20+I20) -> 837404.55
A21: =A20+1 -> 2055 | B21: =B20+1 -> 76.5 | C21: =G20 -> 0 | D21: =H20 -> 837404.55 | E21: =I20 -> 0 | F21: =MAX(0,'BRIDGE CLEAN'!F11*(1+INPUTS!B19)^(A21-'BRIDGE CLEAN'!A11)-IF(B21>=INPUTS!B7,INPUTS!B9*(1+INPUTS!B19)^(A21-INPUTS!B8),0)) -> 25043.986 | G21: =C21*(1+INPUTS!B18) -> 0 | H21: =MAX(0,D21-F21)*(1+INPUTS!B18) -> 852978.6 | I21: =MAX(0,E21-MAX(0,F21-D21))*(1+INPUTS!B18) -> 0 | J21: =IF(B21>INPUTS!B6,"—",G21+H21+I21) -> 852978.6
A22: =A21+1 -> 2056 | B22: =B21+1 -> 77.5 | C22: =G21 -> 0 | D22: =H21 -> 852978.6 | E22: =I21 -> 0 | F22: =MAX(0,'BRIDGE CLEAN'!F11*(1+INPUTS!B19)^(A22-'BRIDGE CLEAN'!A11)-IF(B22>=INPUTS!B7,INPUTS!B9*(1+INPUTS!B19)^(A22-INPUTS!B8),0)) -> 25670.086 | G22: =C22*(1+INPUTS!B18) -> 0 | H22: =MAX(0,D22-F22)*(1+INPUTS!B18) -> 868673.94 | I22: =MAX(0,E22-MAX(0,F22-D22))*(1+INPUTS!B18) -> 0 | J22: =IF(B22>INPUTS!B6,"—",G22+H22+I22) -> 868673.94
A23: =A22+1 -> 2057 | B23: =B22+1 -> 78.5 | C23: =G22 -> 0 | D23: =H22 -> 868673.94 | E23: =I22 -> 0 | F23: =MAX(0,'BRIDGE CLEAN'!F11*(1+INPUTS!B19)^(A23-'BRIDGE CLEAN'!A11)-IF(B23>=INPUTS!B7,INPUTS!B9*(1+INPUTS!B19)^(A23-INPUTS!B8),0)) -> 26311.838 | G23: =C23*(1+INPUTS!B18) -> 0 | H23: =MAX(0,D23-F23)*(1+INPUTS!B18) -> 884480.2 | I23: =MAX(0,E23-MAX(0,F23-D23))*(1+INPUTS!B18) -> 0 | J23: =IF(B23>INPUTS!B6,"—",G23+H23+I23) -> 884480.2
A24: =A23+1 -> 2058 | B24: =B23+1 -> 79.5 | C24: =G23 -> 0 | D24: =H23 -> 884480.2 | E24: =I23 -> 0 | F24: =MAX(0,'BRIDGE CLEAN'!F11*(1+INPUTS!B19)^(A24-'BRIDGE CLEAN'!A11)-IF(B24>=INPUTS!B7,INPUTS!B9*(1+INPUTS!B19)^(A24-INPUTS!B8),0)) -> 26969.634 | G24: =C24*(1+INPUTS!B18) -> 0 | H24: =MAX(0,D24-F24)*(1+INPUTS!B18) -> 900386.1 | I24: =MAX(0,E24-MAX(0,F24-D24))*(1+INPUTS!B18) -> 0 | J24: =IF(B24>INPUTS!B6,"—",G24+H24+I24) -> 900386.1
A25: =A24+1 -> 2059 | B25: =B24+1 -> 80.5 | C25: =G24 -> 0 | D25: =H24 -> 900386.1 | E25: =I24 -> 0 | F25: =MAX(0,'BRIDGE CLEAN'!F11*(1+INPUTS!B19)^(A25-'BRIDGE CLEAN'!A11)-IF(B25>=INPUTS!B7,INPUTS!B9*(1+INPUTS!B19)^(A25-INPUTS!B8),0)) -> 27643.875 | G25: =C25*(1+INPUTS!B18) -> 0 | H25: =MAX(0,D25-F25)*(1+INPUTS!B18) -> 916379.33 | I25: =MAX(0,E25-MAX(0,F25-D25))*(1+INPUTS!B18) -> 0 | J25: =IF(B25>INPUTS!B6,"—",G25+H25+I25) -> 916379.33
A26: =A25+1 -> 2060 | B26: =B25+1 -> 81.5 | C26: =G25 -> 0 | D26: =H25 -> 916379.33 | E26: =I25 -> 0 | F26: =MAX(0,'BRIDGE CLEAN'!F11*(1+INPUTS!B19)^(A26-'BRIDGE CLEAN'!A11)-IF(B26>=INPUTS!B7,INPUTS!B9*(1+INPUTS!B19)^(A26-INPUTS!B8),0)) -> 28334.972 | G26: =C26*(1+INPUTS!B18) -> 0 | H26: =MAX(0,D26-F26)*(1+INPUTS!B18) -> 932446.58 | I26: =MAX(0,E26-MAX(0,F26-D26))*(1+INPUTS!B18) -> 0 | J26: =IF(B26>INPUTS!B6,"—",G26+H26+I26) -> 932446.58
A27: =A26+1 -> 2061 | B27: =B26+1 -> 82.5 | C27: =G26 -> 0 | D27: =H26 -> 932446.58 | E27: =I26 -> 0 | F27: =MAX(0,'BRIDGE CLEAN'!F11*(1+INPUTS!B19)^(A27-'BRIDGE CLEAN'!A11)-IF(B27>=INPUTS!B7,INPUTS!B9*(1+INPUTS!B19)^(A27-INPUTS!B8),0)) -> 29043.346 | G27: =C27*(1+INPUTS!B18) -> 0 | H27: =MAX(0,D27-F27)*(1+INPUTS!B18) -> 948573.39 | I27: =MAX(0,E27-MAX(0,F27-D27))*(1+INPUTS!B18) -> 0 | J27: =IF(B27>INPUTS!B6,"—",G27+H27+I27) -> 948573.39
A28: =A27+1 -> 2062 | B28: =B27+1 -> 83.5 | C28: =G27 -> 0 | D28: =H27 -> 948573.39 | E28: =I27 -> 0 | F28: =MAX(0,'BRIDGE CLEAN'!F11*(1+INPUTS!B19)^(A28-'BRIDGE CLEAN'!A11)-IF(B28>=INPUTS!B7,INPUTS!B9*(1+INPUTS!B19)^(A28-INPUTS!B8),0)) -> 29769.43 | G28: =C28*(1+INPUTS!B18) -> 0 | H28: =MAX(0,D28-F28)*(1+INPUTS!B18) -> 964744.16 | I28: =MAX(0,E28-MAX(0,F28-D28))*(1+INPUTS!B18) -> 0 | J28: =IF(B28>INPUTS!B6,"—",G28+H28+I28) -> 964744.16
A29: =A28+1 -> 2063 | B29: =B28+1 -> 84.5 | C29: =G28 -> 0 | D29: =H28 -> 964744.16 | E29: =I28 -> 0 | F29: =MAX(0,'BRIDGE CLEAN'!F11*(1+INPUTS!B19)^(A29-'BRIDGE CLEAN'!A11)-IF(B29>=INPUTS!B7,INPUTS!B9*(1+INPUTS!B19)^(A29-INPUTS!B8),0)) -> 30513.666 | G29: =C29*(1+INPUTS!B18) -> 0 | H29: =MAX(0,D29-F29)*(1+INPUTS!B18) -> 980942.02 | I29: =MAX(0,E29-MAX(0,F29-D29))*(1+INPUTS!B18) -> 0 | J29: =IF(B29>INPUTS!B6,"—",G29+H29+I29) -> 980942.02
A30: =A29+1 -> 2064 | B30: =B29+1 -> 85.5 | C30: =G29 -> 0 | D30: =H29 -> 980942.02 | E30: =I29 -> 0 | F30: =MAX(0,'BRIDGE CLEAN'!F11*(1+INPUTS!B19)^(A30-'BRIDGE CLEAN'!A11)-IF(B30>=INPUTS!B7,INPUTS!B9*(1+INPUTS!B19)^(A30-INPUTS!B8),0)) -> 31276.507 | G30: =C30*(1+INPUTS!B18) -> 0 | H30: =MAX(0,D30-F30)*(1+INPUTS!B18) -> 997148.79 | I30: =MAX(0,E30-MAX(0,F30-D30))*(1+INPUTS!B18) -> 0 | J30: =IF(B30>INPUTS!B6,"—",G30+H30+I30) -> 997148.79
A31: =A30+1 -> 2065 | B31: =B30+1 -> 86.5 | C31: =G30 -> 0 | D31: =H30 -> 997148.79 | E31: =I30 -> 0 | F31: =MAX(0,'BRIDGE CLEAN'!F11*(1+INPUTS!B19)^(A31-'BRIDGE CLEAN'!A11)-IF(B31>=INPUTS!B7,INPUTS!B9*(1+INPUTS!B19)^(A31-INPUTS!B8),0)) -> 32058.42 | G31: =C31*(1+INPUTS!B18) -> 0 | H31: =MAX(0,D31-F31)*(1+INPUTS!B18) -> 1013344.9 | I31: =MAX(0,E31-MAX(0,F31-D31))*(1+INPUTS!B18) -> 0 | J31: =IF(B31>INPUTS!B6,"—",G31+H31+I31) -> 1013344.9
A32: =A31+1 -> 2066 | B32: =B31+1 -> 87.5 | C32: =G31 -> 0 | D32: =H31 -> 1013344.9 | E32: =I31 -> 0 | F32: =MAX(0,'BRIDGE CLEAN'!F11*(1+INPUTS!B19)^(A32-'BRIDGE CLEAN'!A11)-IF(B32>=INPUTS!B7,INPUTS!B9*(1+INPUTS!B19)^(A32-INPUTS!B8),0)) -> 32859.881 | G32: =C32*(1+INPUTS!B18) -> 0 | H32: =MAX(0,D32-F32)*(1+INPUTS!B18) -> 1029509.3 | I32: =MAX(0,E32-MAX(0,F32-D32))*(1+INPUTS!B18) -> 0 | J32: =IF(B32>INPUTS!B6,"—",G32+H32+I32) -> 1029509.3
A33: =A32+1 -> 2067 | B33: =B32+1 -> 88.5 | C33: =G32 -> 0 | D33: =H32 -> 1029509.3 | E33: =I32 -> 0 | F33: =MAX(0,'BRIDGE CLEAN'!F11*(1+INPUTS!B19)^(A33-'BRIDGE CLEAN'!A11)-IF(B33>=INPUTS!B7,INPUTS!B9*(1+INPUTS!B19)^(A33-INPUTS!B8),0)) -> 33681.378 | G33: =C33*(1+INPUTS!B18) -> 0 | H33: =MAX(0,D33-F33)*(1+INPUTS!B18) -> 1045619.3 | I33: =MAX(0,E33-MAX(0,F33-D33))*(1+INPUTS!B18) -> 0 | J33: =IF(B33>INPUTS!B6,"—",G33+H33+I33) -> 1045619.3
A34: =A33+1 -> 2068 | B34: =B33+1 -> 89.5 | C34: =G33 -> 0 | D34: =H33 -> 1045619.3 | E34: =I33 -> 0 | F34: =MAX(0,'BRIDGE CLEAN'!F11*(1+INPUTS!B19)^(A34-'BRIDGE CLEAN'!A11)-IF(B34>=INPUTS!B7,INPUTS!B9*(1+INPUTS!B19)^(A34-INPUTS!B8),0)) -> 34523.412 | G34: =C34*(1+INPUTS!B18) -> 0 | H34: =MAX(0,D34-F34)*(1+INPUTS!B18) -> 1061650.7 | I34: =MAX(0,E34-MAX(0,F34-D34))*(1+INPUTS!B18) -> 0 | J34: =IF(B34>INPUTS!B6,"—",G34+H34+I34) -> 1061650.7

Sheet PROJECTION
A1: FULL LIFETIME PROJECTION
A2: Year | B2: Age | C2: Total Portfolio | D2: Annual Withdrawal | E2: Phase
A3: ='BRIDGE CLEAN'!A4 -> 2030 | B3: ='BRIDGE CLEAN'!B4 -> 52 | C3: ='BRIDGE CLEAN'!J4 -> 861000 | D3: ='BRIDGE CLEAN'!F4 -> 40000 | E3: Bridge (Taxable)
A4: ='BRIDGE CLEAN'!A5 -> 2031 | B4: ='BRIDGE CLEAN'!B5 -> 53 | C4: ='BRIDGE CLEAN'!J5 -> 861000 | D4: ='BRIDGE CLEAN'!F5 -> 41000 | E4: Bridge (Taxable)
A5: ='BRIDGE CLEAN'!A6 -> 2032 | B5: ='BRIDGE CLEAN'!B6 -> 54 | C5: ='BRIDGE CLEAN'!J6 -> 859923.75 | D5: ='BRIDGE CLEAN'!F6 -> 42025 | E5: Bridge (Taxable)
A6: ='BRIDGE CLEAN'!A7 -> 2033 | B6: ='BRIDGE CLEAN'!B7 -> 55 | C6: ='BRIDGE CLEAN'!J7 -> 857690.53 | D6: ='BRIDGE CLEAN'!F7 -> 43075.625 | E6: Bridge (Taxable)
A7: ='BRIDGE CLEAN'!A8 -> 2034 | B7: ='BRIDGE CLEAN'!B8 -> 56 | C7: ='BRIDGE CLEAN'!J8 -> 854214.92 | D7: ='BRIDGE CLEAN'!F8 -> 44152.516 | E7: Bridge (Taxable)
A8: ='BRIDGE CLEAN'!A9 -> 2035 | B8: ='BRIDGE CLEAN'!B9 -> 57 | C8: ='BRIDGE CLEAN'!J9 -> 849406.52 | D8: ='BRIDGE CLEAN'!F9 -> 45256.329 | E8: Bridge (Taxable)
A9: ='BRIDGE CLEAN'!A10 -> 2036 | B9: ='BRIDGE CLEAN'!B10 -> 58 | C9: ='BRIDGE CLEAN'!J10 -> 843169.72 | D9: ='BRIDGE CLEAN'!F10 -> 46387.737 | E9: Bridge (Taxable)
A10: ='BRIDGE CLEAN'!A11 -> 2037 | B10: ='BRIDGE CLEAN'!B11 -> 59 | C10: ='BRIDGE CLEAN'!J11 -> 835403.4 | D10: ='BRIDGE CLEAN'!F11 -> 47547.43 | E10: Bridge (Taxable)
A11: ='POST-59.5'!A4 -> 2038 | B11: ='POST-59.5'!B4 -> 59.5 | C11: ='POST-59.5'!J4 -> 826000.65 | D11: ='POST-59.5'!F4 -> 48736.116 | E11: =IF('POST-59.5'!B4>=INPUTS!B7,"Post-SS (401k+)","Post-59½ (401k)") -> Post-59½ (401k)
A12: ='POST-59.5'!A5 -> 2039 | B12: ='POST-59.5'!B5 -> 60.5 | C12: ='POST-59.5'!J5 -> 814848.44 | D12: ='POST-59.5'!F5 -> 49954.519 | E12: =IF('POST-59.5'!B5>=INPUTS!B7,"Post-SS (401k+)","Post-59½ (401k)") -> Post-59½ (401k)
A13: ='POST-59.5'!A6 -> 2040 | B13: ='POST-59.5'!B6 -> 61.5 | C13: ='POST-59.5'!J6 -> 801827.31 | D13: ='POST-59.5'!F6 -> 51203.382 | E13: =IF('POST-59.5'!B6>=INPUTS!B7,"Post-SS (401k+)","Post-59½ (401k)") -> Post-59½ (401k)
A14: ='POST-59.5'!A7 -> 2041 | B14: ='POST-59.5'!B7 -> 62.5 | C14: ='POST-59.5'!J7 -> 786811.04 | D14: ='POST-59.5'!F7 -> 52483.466 | E14: =IF('POST-59.5'!B7>=INPUTS!B7,"Post-SS (401k+)","Post-59½ (401k)") -> Post-59½ (401k)
A15: ='POST-59.5'!A8 -> 2042 | B15: ='POST-59.5'!B8 -> 63.5 | C15: ='POST-59.5'!J8 -> 769666.26 | D15: ='POST-59.5'!F8 -> 53795.553 | E15: =IF('POST-59.5'!B8>=INPUTS!B7,"Post-SS (401k+)","Post-59½ (401k)") -> Post-59½ (401k)
A16: ='POST-59.5'!A9 -> 2043 | B16: ='POST-59.5'!B9 -> 64.5 | C16: ='POST-59.5'!J9 -> 750252.11 | D16: ='POST-59.5'!F9 -> 55140.442 | E16: =IF('POST-59.5'!B9>=INPUTS!B7,"Post-SS (401k+)","Post-59½ (401k)") -> Post-59½ (401k)
A17: ='POST-59.5'!A10 -> 2044 | B17: ='POST-59.5'!B10 -> 65.5 | C17: ='POST-59.5'!J10 -> 728419.81 | D17: ='POST-59.5'!F10 -> 56518.953 | E17: =IF('POST-59.5'!B10>=INPUTS!B7,"Post-SS (401k+)","Post-59½ (401k)") -> Post-59½ (401k)
A18: ='POST-59.5'!A11 -> 2045 | B18: ='POST-59.5'!B11 -> 66.5 | C18: ='POST-59.5'!J11 -> 704012.28 | D18: ='POST-59.5'!F11 -> 57931.927 | E18: =IF('POST-59.5'!B11>=INPUTS!B7,"Post-SS (401k+)","Post-59½ (401k)") -> Post-59½ (401k)
A19: ='POST-59.5'!A12 -> 2046 | B19: ='POST-59.5'!B12 -> 67.5 | C19: ='POST-59.5'!J12 -> 718156.79 | D19: ='POST-59.5'!F12 -> 20053.43 | E19: =IF('POST-59.5'!B12>=INPUTS!B7,"Post-SS (401k+)","Post-59½ (401k)") -> Post-SS (401k+)
A20: ='POST-59.5'!A13 -> 2047 | B20: ='POST-59.5'!B13 -> 68.5 | C20: ='POST-59.5'!J13 -> 732482.13 | D20: ='POST-59.5'!F13 -> 20554.766 | E20: =IF('POST-59.5'!B13>=INPUTS!B7,"Post-SS (401k+)","Post-59½ (401k)") -> Post-SS (401k+)
A21: ='POST-59.5'!A14 -> 2048 | B21: ='POST-59.5'!B14 -> 69.5 | C21: ='POST-59.5'!J14 -> 746984.17 | D21: ='POST-59.5'!F14 -> 21068.635 | E21: =IF('POST-59.5'!B14>=INPUTS!B7,"Post-SS (401k+)","Post-59½ (401k)") -> Post-SS (401k+)
A22: ='POST-59.5'!A15 -> 2049 | B22: ='POST-59.5'!B15 -> 70.5 | C22: ='POST-59.5'!J15 -> 761658.26 | D22: ='POST-59.5'!F15 -> 21595.351 | E22: =IF('POST-59.5'!B15>=INPUTS!B7,"Post-SS (401k+)","Post-59½ (401k)") -> Post-SS (401k+)
A23: ='POST-59.5'!A16 -> 2050 | B23: ='POST-59.5'!B16 -> 71.5 | C23: ='POST-59.5'!J16 -> 776499.17 | D23: ='POST-59.5'!F16 -> 22135.235 | E23: =IF('POST-59.5'!B16>=INPUTS!B7,"Post-SS (401k+)","Post-59½ (401k)") -> Post-SS (401k+)
A24: ='POST-59.5'!A17 -> 2051 | B24: ='POST-59.5'!B17 -> 72.5 | C24: ='POST-59.5'!J17 -> 791501.09 | D24: ='POST-59.5'!F17 -> 22688.616 | E24: =IF('POST-59.5'!B17>=INPUTS!B7,"Post-SS (401k+)","Post-59½ (401k)") -> Post-SS (401k+)
A25: ='POST-59.5'!A18 -> 2052 | B25: ='POST-59.5'!B18 -> 73.5 | C25: ='POST-59.5'!J18 -> 806657.52 | D25: ='POST-59.5'!F18 -> 23255.831 | E25: =IF('POST-59.5'!B18>=INPUTS!B7,"Post-SS (401k+)","Post-59½ (401k)") -> Post-SS (401k+)
A26: ='POST-59.5'!A19 -> 2053 | B26: ='POST-59.5'!B19 -> 74.5 | C26: ='POST-59.5'!J19 -> 821961.3 | D26: ='POST-59.5'!F19 -> 23837.227 | E26: =IF('POST-59.5'!B19>=INPUTS!B7,"Post-SS (401k+)","Post-59½ (401k)") -> Post-SS (401k+)
A27: ='POST-59.5'!A20 -> 2054 | B27: ='POST-59.5'!B20 -> 75.5 | C27: ='POST-59.5'!J20 -> 837404.55 | D27: ='POST-59.5'!F20 -> 24433.158 | E27: =IF('POST-59.5'!B20>=INPUTS!B7,"Post-SS (401k+)","Post-59½ (401k)") -> Post-SS (401k+)
A28: ='POST-59.5'!A21 -> 2055 | B28: ='POST-59.5'!B21 -> 76.5 | C28: ='POST-59.5'!J21 -> 852978.6 | D28: ='POST-59.5'!F21 -> 25043.986 | E28: =IF('POST-59.5'!B21>=INPUTS!B7,"Post-SS (401k+)","Post-59½ (401k)") -> Post-SS (401k+)
A29: ='POST-59.5'!A22 -> 2056 | B29: ='POST-59.5'!B22 -> 77.5 | C29: ='POST-59.5'!J22 -> 868673.94 | D29: ='POST-59.5'!F22 -> 25670.086 | E29: =IF('POST-59.5'!B22>=INPUTS!B7,"Post-SS (401k+)","Post-59½ (401k)") -> Post-SS (401k+)
A30: ='POST-59.5'!A23 -> 2057 | B30: ='POST-59.5'!B23 -> 78.5 | C30: ='POST-59.5'!J23 -> 884480.2 | D30: ='POST-59.5'!F23 -> 26311.838 | E30: =IF('POST-59.5'!B23>=INPUTS!B7,"Post-SS (401k+)","Post-59½ (401k)") -> Post-SS (401k+)
A31: ='POST-59.5'!A24 -> 2058 | B31: ='POST-59.5'!B24 -> 79.5 | C31: ='POST-59.5'!J24 -> 900386.1 | D31: ='POST-59.5'!F24 -> 26969.634 | E31: =IF('POST-59.5'!B24>=INPUTS!B7,"Post-SS (401k+)","Post-59½ (401k)") -> Post-SS (401k+)
A32: ='POST-59.5'!A25 -> 2059 | B32: ='POST-59.5'!B25 -> 80.5 | C32: ='POST-59.5'!J25 -> 916379.33 | D32: ='POST-59.5'!F25 -> 27643.875 | E32: =IF('POST-59.5'!B25>=INPUTS!B7,"Post-SS (401k+)","Post-59½ (401k)") -> Post-SS (401k+)
A33: ='POST-59.5'!A26 -> 2060 | B33: ='POST-59.5'!B26 -> 81.5 | C33: ='POST-59.5'!J26 -> 932446.58 | D33: ='POST-59.5'!F26 -> 28334.972 | E33: =IF('POST-59.5'!B26>=INPUTS!B7,"Post-SS (401k+)","Post-59½ (401k)") -> Post-SS (401k+)
A34: ='POST-59.5'!A27 -> 2061 | B34: ='POST-59.5'!B27 -> 82.5 | C34: ='POST-59.5'!J27 -> 948573.39 | D34: ='POST-59.5'!F27 -> 29043.346 | E34: =IF('POST-59.5'!B27>=INPUTS!B7,"Post-SS (401k+)","Post-59½ (401k)") -> Post-SS (401k+)
A35: ='POST-59.5'!A28 -> 2062 | B35: ='POST-59.5'!B28 -> 83.5 | C35: ='POST-59.5'!J28 -> 964744.16 | D35: ='POST-59.5'!F28 -> 29769.43 | E35: =IF('POST-59.5'!B28>=INPUTS!B7,"Post-SS (401k+)","Post-59½ (401k)") -> Post-SS (401k+)
A36: ='POST-59.5'!A29 -> 2063 | B36: ='POST-59.5'!B29 -> 84.5 | C36: ='POST-59.5'!J29 -> 980942.02 | D36: ='POST-59.5'!F29 -> 30513.666 | E36: =IF('POST-59.5'!B29>=INPUTS!B7,"Post-SS (401k+)","Post-59½ (401k)") -> Post-SS (401k+)
A37: ='POST-59.5'!A30 -> 2064 | B37: ='POST-59.5'!B30 -> 85.5 | C37: ='POST-59.5'!J30 -> 997148.79 | D37: ='POST-59.5'!F30 -> 31276.507 | E37: =IF('POST-59.5'!B30>=INPUTS!B7,"Post-SS (401k+)","Post-59½ (401k)") -> Post-SS (401k+)
A38: ='POST-59.5'!A31 -> 2065 | B38: ='POST-59.5'!B31 -> 86.5 | C38: ='POST-59.5'!J31 -> 1013344.9 | D38: ='POST-59.5'!F31 -> 32058.42 | E38: =IF('POST-59.5'!B31>=INPUTS!B7,"Post-SS (401k+)","Post-59½ (401k)") -> Post-SS (401k+)
A39: ='POST-59.5'!A32 -> 2066 | B39: ='POST-59.5'!B32 -> 87.5 | C39: ='POST-59.5'!J32 -> 1029509.3 | D39: ='POST-59.5'!F32 -> 32859.881 | E39: =IF('POST-59.5'!B32>=INPUTS!B7,"Post-SS (401k+)","Post-59½ (401k)") -> Post-SS (401k+)
A40: ='POST-59.5'!A33 -> 2067 | B40: ='POST-59.5'!B33 -> 88.5 | C40: ='POST-59.5'!J33 -> 1045619.3 | D40: ='POST-59.5'!F33 -> 33681.378 | E40: =IF('POST-59.5'!B33>=INPUTS!B7,"Post-SS (401k+)","Post-59½ (401k)") -> Post-SS (401k+)
...

Sheet RISK FLAGS
A1: ⚠️ AUTOMATIC RISK FLAGS
A2: Risk Check | B2: Status | C2: Detail
A3: Taxable account fully funds bridge? | B3: =IF('BRIDGE CLEAN'!G11>0,"✅ Fully Funded","⚠️ Gap Exists") -> ⚠️ Gap Exists | C3: =IF('BRIDGE CLEAN'!G11>0,"Taxable covers all bridge years without touching 401k","Taxable runs out during bridge — Roth and/or 401k needed. See BRIDGE CLEAN for the exact year.") -> Taxable runs out during bridge — Roth and/or 401k needed. See BRIDGE CLEAN for the exact year.
A4: Portfolio intact at life expectancy? | B4: =IF(ISNUMBER(PROJECTION!C41),IF(PROJECTION!C41>0,"✅ Solvent","❌ Depleted"),"✅ Solvent") -> ✅ Solvent | C4: =IF(ISNUMBER(PROJECTION!C41),IF(PROJECTION!C41>0,"Portfolio positive at life expectancy","Portfolio depleted — reduce spending or increase savings"),"Portfolio intact") -> Portfolio positive at life expectancy
A5: Retirement age > current age? | B5: =IF(INPUTS!B5>INPUTS!B4,"✅ Valid","❌ Fix Ages") -> ✅ Valid | C5: =IF(INPUTS!B5>INPUTS!B4,"Ages are valid","Error: retirement age must be greater than current age") -> Ages are valid
A6: Withdrawal rate ≤ 4%? | B6: =IF(INPUTS!B17/(INPUTS!B11+INPUTS!B12+INPUTS!B13)<=0.04,"✅ Safe","⚠️ High Rate") -> ⚠️ High Rate | C6: =IFERROR("Rate: "&TEXT(INPUTS!B17/(INPUTS!B11+INPUTS!B12+INPUTS!B13),"0.0%")&IF(INPUTS!B17/(INPUTS!B11+INPUTS!B12+INPUTS!B13)<=0.04," — within safe range"," — consider reducing spending"),"Check inputs") -> Rate: 4.7% — consider reducing spending
A7: Bridge years fully covered? | B7: =IF('BRIDGE CLEAN'!J11>0,"✅ Covered","⚠️ Review") -> ✅ Covered | C7: =IF('BRIDGE CLEAN'!J11>0,"Combined accounts cover the bridge period","Bridge period exceeds available funds — see BRIDGE CLEAN") -> Combined accounts cover the bridge period
A9: ⚡ Additional checks available in Pro:
A10: ACA subsidy cliff risk? | B10: 🔒 PRO FEATURE | C10: Upgrade to check if bridge income eliminates ACA premium tax credits
A11: SS delay opportunity? | B11: 🔒 PRO FEATURE | C11: Upgrade to see exact dollar impact of delaying Social Security to 70
A12: Roth conversion window? | B12: 🔒 PRO FEATURE | C12: Upgrade to detect low-income bridge years optimal for Roth conversions
